Workbook

Sheet README
B2: MDC 模块化数据中心 · 国内项目可研财务测算模板 v1.0（2026-09-16）
B3: 配套 MDC-KB `KB/Guideline/FEASIBILITY_Guideline.md` §F-2 第 6 章 / §F-4 / §F-7。每个国内可研复制本工作簿到 `Projects/<项目名>/可研/`，重命名为 `<项目名>_可研财务测算_v<x>.xlsx`。
B5: 铁律
B6: 1. 货币与税口径：国内方案一律人民币（含税）；海外方案一律美元（未税）。本模板为国内版，所有单价按含税输入，模型内按税率还原不含税值参与经济评价；校核 C10 锁定。
B7: 2. 单一真值源：所有输入只在 `0_参数`、`1-1_建安工程费`、`1-2_设备及软件` 三页的蓝字/黄底单元格；其余全部公式，不得手改。可研正文数字只准从 `00_指标表` 与对应附表引用。
B8: 3. 业主参数：黄底单元格（GPU/服务器单价、算力单价、售卖比例、算力设备折旧年限等）由业主/算力运营方书面提供，'来源/说明'列注明依据文件；我方不自行给 GPU 报价。
B9: 4. 出稿门禁：`13_一致性校核` 全部 OK 才可导出附表；任何 ERR 先改方案与参数，不得改公式凑数。
B11: 颜色约定
B12: 蓝字 = 输入；黄底 = 业主提供；黑字 = 本表公式；绿字 = 跨表引用；灰底 = 表头；浅绿底 = 关键结果。
B14: 填写顺序
B15: ① 0_参数 A–K 组（规模 → 负荷 → 收入 → 成本 → 折旧 → 税 → 融资 → 流动资金 → 费率 → 运营年参数） → ② 1-2 设备及软件（A 块业主价格、B 块我方口径） → ③ 1-1 建安工程费 → ④ 看 13_一致性校核 → ⑤ 看 00_指标表 → ⑥ 12_敏感性（Excel 中按 F9 重算数据表） → ⑦ 附表 1–12 导出 PDF 附于可研。
B17: 附表与可研章节对应
... B30: 示例数值参照阳高县智算中心可研（2026-04）口径设置，仅示意；新项目逐项替换。示例中模块单价、电力舱、冷源模块价格为占位数字，不代表报价。

Sheet 00_指标表
A1: 可研 1.1.10 主要技术经济指标一览表（正文唯一引用源）
A2: 本表全部为公式；可研正文与各章数字只准从本表与对应附表引用，不得另行手填
A4: 序号 | B4: 指标 | C4: 单位 | D4: 数值 | E4: 备注 / 来源表
A5: 1 | B5: 建设规模指标
A6: 1.1 | B6: 模块化算力单元数量 | C6: 套 | D6: =0_参数!$C$18 -> 4 | E6: 参数 B1
A7: 1.2 | B7: IT 总功率 | C7: kW | D7: =0_参数!$C$20 -> 2112 | E7: 参数 B3
A8: 1.3 | B8: 折合标准机架（2.5kW） | C8: 架 | D8: =0_参数!$C$22 -> 844.8 | E8: 参数 B5；备案/能评口径
A9: 1.4 | B9: 服务器台数 | C9: 台 | D9: =0_参数!$C$23 -> 168 | E9: 参数 B6【业主】
A10: 1.5 | B10: 总算力（FP16 稠密） | C10: P | D10: =0_参数!$C$25 -> 3024 | E10: 参数 B8
A11: 1.6 | B11: 配套用房建筑面积 | C11: ㎡ | D11: =0_参数!$C$30 -> 1500 | E11: 参数 C2
A12: 2 | B12: 能耗与能效
A13: 2.1 | B13: 总有功功率 | C13: kW | D13: =0_参数!$C$34 -> 2537.16 | E13: 参数 C6（供电章负荷计算）
A14: 2.2 | B14: 正常年用电量 | C14: 万kWh | D14: =INDEX(4_总成本费用!D$11:U$11,0_参数!$C$9+0_参数!$C$15) -> 1791.989 | E14: 附表 4；能评章同源
A15: 2.3 | B15: 正常年 IT 用电量 | C15: 万kWh | D15: =INDEX(4_总成本费用!D$10:U$10,0_参数!$C$9+0_参数!$C$15) -> 1498.5907 | E15: 附表 4
A16: 2.4 | B16: 设计 PUE | D16: =0_参数!$C$29 -> 1.18 | E16: 参数 C1
A17: 2.5 | B17: 正常年用水量 | C17: m³ | D17: =INDEX(4_总成本费用!D$12:U$12,0_参数!$C$9+0_参数!$C$15) -> 16000 | E17: 附表 4
A18: 2.6 | B18: WUE | C18: L/kWh | D18: =IFERROR(D17*1000/(D15*10000),0) -> 1.0676698 | E18: ＝ 用水量(L) / IT 电量(kWh)
A19: 3 | B19: 建设与运营
A20: 3.1 | B20: 建设期 | C20: 年 | D20: =0_参数!$C$9 -> 1 | E20: 参数 A4
A21: 3.2 | B21: 运营期 | C21: 年 | D21: =0_参数!$C$10 -> 10 | E21: 参数 A5
A22: 3.3 | B22: 劳动定员 | C22: 人 | D22: =0_参数!$C$67 -> 36 | E22: 参数 E14 = 可研 5.3.2
A23: 4 | B23: 投资指标
A24: 4.1 | B24: 项目总投资 | C24: 万元 | D24: =1_总投资估算!$G$33 -> 124539.38 | E24: 附表 1
A25: 4.1.1 | B25: 建设工程费 | C25: 万元 | D25: =1_总投资估算!$G$5 -> 110463.8 | E25: 附表 1
A26: 4.1.2 | B26: 工程建设其他费用 | C26: 万元 | D26: =1_总投资估算!$G$8 -> 6123.8248 | E26: 附表 1
A27: 4.1.3 | B27: 预备费 | C27: 万元 | D27: =1_总投资估算!$G$26 -> 5829.3812 | E27: 附表 1
A28: 4.1.4 | B28: 建设期利息 | C28: 万元 | D28: =1_总投资估算!$G$30 -> 1536.2551 | E28: 附表 1 / 11
A29: 4.1.5 | B29: 铺底流动资金 | C29: 万元 | D29: =1_总投资估算!$G$32 -> 586.12245 | E29: 附表 1 / 2
A30: 4.2 | B30: 其中：算力设备投资（业主提供价格） | C30: 万元 | D30: ='1-2_设备及软件'!$F$12 -> 94250 | E30: 附表 1-2 A
A31: 4.3 | B31: 其中：基础设施设备投资 | C31: 万元 | D31: ='1-2_设备及软件'!$F$22 -> 13402 | E31: 附表 1-2 B
A32: 4.4 | B32: 资金筹措：自有资金 / 长期借款 | C32: 万元 | D32: =0_参数!$C$89 -> 20000 | E32: 参数 H1；借款 = 附表 3
A33: 5 | B33: 财务指标
A34: 5.1 | B34: 营业收入（正常年，不含税） | C34: 万元 | D34: =INDEX(6_收入税金!D$11:U$11,0_参数!$C$9+0_参数!$C$15) -> 23963.774 | E34: 附表 6
A35: 5.2 | B35: 总成本费用（平均年） | C35: 万元 | D35: =4_总成本费用!$V$27 -> 15898.982 | E35: 附表 4
A36: 5.3 | B36: 利润总额（平均年） | C36: 万元 | D36: =7_利润!$V$12 -> 7798.5276 | E36: 附表 7
A37: 5.4 | B37: 所得税（平均年） | C37: 万元 | D37: =7_利润!$V$14 -> 1949.6319 | E37: 附表 7
A38: 5.5 | B38: 净利润（平均年） | C38: 万元 | D38: =7_利润!$V$15 -> 5848.8957 | E38: 附表 7
A39: 5.6 | B39: 投资利润率 | C39: % | D39: =8_现金流量!$D$39 -> 0.062618968 | E39: 附表 8
A40: 5.7 | B40: 投资利税率 | C40: % | D40: =8_现金流量!$D$40 -> 0.062618968 | E40: 附表 8
A41: 5.8 | B41: 财务内部收益率（税前） | C41: % | D41: =8_现金流量!$D$29 -> 0.10281066 | E41: 附表 8
...

Sheet 0_参数
A1: 0 参数与假设（全模型唯一输入页）
A2: 颜色约定：蓝字 = 输入；黄底 = 业主/算力运营方提供并注明来源；黑字 = 公式；绿字 = 跨表引用。单位：万元 / 人民币（含税）
A4: A 项目与口径
A5: 编号 | B5: 参数 | C5: 数值 | D5: 单位 | E5: 来源 / 说明
A6: A1 | B6: 项目名称 | C6: 示例：XX 县模块化智算中心项目 | E6: 与可研封面一致
A7: A2 | B7: 货币与税口径（铁律） | C7: 人民币（含税） | E7: 国内方案一律人民币、含税报价；海外方案一律美元、未税。本模板为国内版，单价输入均为含税价，模型内按税率还原不含税值
A8: A3 | B8: 价格水平基准年 | C8: 2026 | D8: 年 | E8: 文本
A9: A4 | B9: 建设期 | C9: 1 | D9: 年 | E9: 1–3；MDC 模块化项目通常 1 年（工厂制造 ∥ 现场土建外线）
A10: A5 | B10: 运营期 | C10: 10 | D10: 年 | E10: ≤15；可研通常取 10 年
A11: A6 | B11: 建设投资投入比例-建设第1年 | C11: 1 | E11: 建设期各年比例之和须 = 1（校核表 C1）
A12: A7 | B12: 建设投资投入比例-建设第2年 | C12: 0
A13: A8 | B13: 建设投资投入比例-建设第3年 | C13: 0
A14: A9 | B14: 基准收益率 ic | C14: 0.08 | E14: 《建设项目经济评价方法与参数》第三版 行业基准
A15: A10 | B15: 正常年 = 运营第几年 | C15: 3 | E15: 用于盈亏平衡与指标表'正常年'取值；须 ≤ 运营期
A16: B 建设规模（与可研 1.1.10 指标表锁定）
A17: 编号 | B17: 参数 | C17: 数值 | D17: 单位 | E17: 来源 / 说明
A18: B1 | B18: 模块化算力单元数量 | C18: 4 | D18: 套 | E18: 一期模块数；分期投产比例见 D 组运营年参数
A19: B2 | B19: 单模块 IT 功率 | C19: 528 | D19: kW | E19: 产品口径
A20: B3 | B20: IT 总功率 | C20: =0_参数!$C$18*0_参数!$C$19 -> 2112 | D20: kW | E20: ＝ 模块数 × 单模块 IT 功率
A21: B4 | B21: 标准机架折算功率 | C21: 2.5 | D21: kW/架 | E21: 工信部标准机架口径
A22: B5 | B22: 折合标准机架 | C22: =0_参数!$C$20/0_参数!$C$21 -> 844.8 | D22: 架 | E22: 备案/能评口径
A23: B6 | B23: 服务器台数 | C23: 168 | D23: 台 | E23: 【业主提供】算力设备清单数量，与附表1-2 一致（校核表 C3）
A24: B7 | B24: 单台算力（FP16 稠密） | C24: 18 | D24: P | E24: 【业主提供】注明精度与稠密/稀疏
A25: B8 | B25: 总算力 | C25: =0_参数!$C$23*0_参数!$C$24 -> 3024 | D25: P
A26: B9 | B26: 可售计价单元数 | C26: =0_参数!$C$23 -> 168 | D26: 台 | E26: 默认 = 服务器台数；按机柜计价时改为机柜数
A27: C 负荷与能耗（可研'一张负荷表'，供电章 / 能评章 / 财务章同源）
A28: 编号 | B28: 参数 | C28: 数值 | D28: 单位 | E28: 来源 / 说明
A29: C1 | B29: 设计 PUE | C29: 1.18 | E29: GB 40879-2021 口径；与可研 7.4 计算值一致
A30: C2 | B30: 配套用房建筑面积 | C30: 1500 | D30: ㎡ | E30: 运维楼 / 柴发房 / 值班等
A31: C3 | B31: 配套用房单位负荷 | C31: 30 | D31: W/㎡
A32: C4 | B32: 配套用房功率 | C32: =0_参数!$C$30*0_参数!$C$31/1000 -> 45 | D32: kW
A33: C5 | B33: 配套机电功率（冷却+供配电损耗） | C33: =0_参数!$C$20*(0_参数!$C$29-1) -> 380.16 | D33: kW | E33: ＝ IT × (PUE−1)，不用 30% 平铺
A34: C6 | B34: 总有功功率 | C34: =0_参数!$C$20+0_参数!$C$32+0_参数!$C$33 -> 2537.16 | D34: kW | E34: 供电章负荷计算结论
A35: C7 | B35: 配套用房需要系数 | C35: 0.6
A36: C8 | B36: 年运行小时 | C36: 8760 | D36: h
A37: C9 | B37: 满负荷年用水量 | C37: 16000 | D37: m³ | E37: 取自可研 4.3.5 用水量表（采暖期+非采暖期）
A38: C10 | B38: 电价（含税） | C38: 0.45 | D38: 元/kWh | E38: 当地大工业/直供电价，含税
A39: C11 | B39: 电力增值税率 | C39: 0.13
A40: C12 | B40: 水价（含税） | C40: 4.5 | D40: 元/m³
A41: C13 | B41: 水增值税率 | C41: 0.09
...

Sheet 1_总投资估算
A1: 附表 1 总投资估算表
A2: 单位：万元（人民币，含税）。第一部分来自附表 1-1 / 1-2；其他费用按参数 J 组费率；建设期利息来自附表 11；铺底流动资金来自附表 2
A4: 序号 | B4: 工程或费用名称 | C4: 建筑工程 | D4: 安装工程 | E4: 设备购置 | F4: 其他费用 | G4: 合计 | H4: 占总投资 | I4: 资产归类 / 说明
A5: 一 | B5: 第一部分 建设工程费用 | C5: =C6+C7 -> 1891.8 | D5: =D6+D7 -> 920 | E5: =E6+E7 -> 107652 | G5: =SUM(C5:F5) -> 110463.8 | H5: =IFERROR(G5/$G$33,0) -> 0.88697886
A6: 1 | B6: 设备及软件工程 | E6: ='1-2_设备及软件'!$F$23 -> 107652 | G6: =SUM(C6:F6) -> 107652 | H6: =IFERROR(G6/$G$33,0) -> 0.86440126 | I6: 固定资产（分算力/基础设施两类，见附表5）
A7: 2 | B7: 建筑安装工程 | C7: ='1-1_建安工程费'!$G$16 -> 1891.8 | D7: ='1-1_建安工程费'!$H$16 -> 920 | G7: =SUM(C7:F7) -> 2811.8 | H7: =IFERROR(G7/$G$33,0) -> 0.022577597 | I7: 固定资产（建筑类）
A8: 二 | B8: 第二部分 工程建设其他费用 | F8: =SUM(F9:F25) -> 6123.8248 | G8: =SUM(C8:F8) -> 6123.8248 | H8: =IFERROR(G8/$G$33,0) -> 0.049171793
A9: 2.1 | B9: 土地费 | F9: =0_参数!$C$104 -> 330 | G9: =SUM(C9:F9) -> 330 | H9: =IFERROR(G9/$G$33,0) -> 0.0026497642 | I9: 固定资产
A10: 2.2 | B10: 建设单位管理费 | F10: =$G$5*0_参数!$C$105 -> 1436.0294 | G10: =SUM(C10:F10) -> 1436.0294 | H10: =IFERROR(G10/$G$33,0) -> 0.011530725 | I10: 固定资产
A11: 2.3 | B11: 工程监理费 | F11: =($C$7+$D$7+$E$6*0.4)*0_参数!$C$106 -> 596.3438 | G11: =SUM(C11:F11) -> 596.3438 | H11: =IFERROR(G11/$G$33,0) -> 0.0047883953 | I11: 固定资产
A12: 2.4 | B12: 勘察费 | F12: =($C$7+$D$7)*0_参数!$C$107 -> 11.2472 | G12: =SUM(C12:F12) -> 11.2472 | H12: =IFERROR(G12/$G$33,0) -> 9.0310388e-05 | I12: 固定资产
A13: 2.5 | B13: 设计费 | F13: =($C$7+$D$7+$E$6)*0_参数!$C$108 -> 1877.8846 | G13: =SUM(C13:F13) -> 1877.8846 | H13: =IFERROR(G13/$G$33,0) -> 0.015078641 | I13: 固定资产
A14: 2.6 | B14: 可行性研究报告编制费 | F14: =0_参数!$C$109 -> 30 | G14: =SUM(C14:F14) -> 30 | H14: =IFERROR(G14/$G$33,0) -> 0.00024088765 | I14: 固定资产
A15: 2.7 | B15: 节能报告编制费 | F15: =0_参数!$C$110 -> 50 | G15: =SUM(C15:F15) -> 50 | H15: =IFERROR(G15/$G$33,0) -> 0.00040147942 | I15: 固定资产
A16: 2.8 | B16: 环评及其他专项评价费 | F16: =0_参数!$C$111 -> 40 | G16: =SUM(C16:F16) -> 40 | H16: =IFERROR(G16/$G$33,0) -> 0.00032118354 | I16: 固定资产
A17: 2.9 | B17: 招标代理费 | F17: =$G$5*0_参数!$C$112 -> 220.9276 | G17: =SUM(C17:F17) -> 220.9276 | H17: =IFERROR(G17/$G$33,0) -> 0.0017739577 | I17: 固定资产
A18: 2.10 | B18: 场地准备及临时设施费 | F18: =($C$7+$D$7)*0_参数!$C$113 -> 22.4944 | G18: =SUM(C18:F18) -> 22.4944 | H18: =IFERROR(G18/$G$33,0) -> 0.00018062078 | I18: 固定资产
A19: 2.11 | B19: 工程保险费 | F19: =($C$7+$D$7)*0_参数!$C$114+$E$6*0_参数!$C$115 -> 379.03144 | G19: =SUM(C19:F19) -> 379.03144 | H19: =IFERROR(G19/$G$33,0) -> 0.0030434665 | I19: 固定资产
A20: 2.12 | B20: 联合试运转费 | F20: =$E$6*0_参数!$C$116 -> 1076.52 | G20: =SUM(C20:F20) -> 1076.52 | H20: =IFERROR(G20/$G$33,0) -> 0.0086440126 | I20: 固定资产
A21: 2.13 | B21: 竣工决算编制费 | F21: =$G$5*0_参数!$C$117 -> 11.04638 | G21: =SUM(C21:F21) -> 11.04638 | H21: =IFERROR(G21/$G$33,0) -> 8.8697886e-05 | I21: 固定资产
A22: 2.14 | B22: 办公家具购置费 | F22: =0_参数!$C$118 -> 5.1 | G22: =SUM(C22:F22) -> 5.1 | H22: =IFERROR(G22/$G$33,0) -> 4.0950901e-05 | I22: 递延资产
A23: 2.15 | B23: 职工培训费 | F23: =0_参数!$C$119 -> 7.2 | G23: =SUM(C23:F23) -> 7.2 | H23: =IFERROR(G23/$G$33,0) -> 5.7813037e-05 | I23: 递延资产
A24: 2.16 | B24: 提前进场费 | F24: =0_参数!$C$120 -> 30 | G24: =SUM(C24:F24) -> 30 | H24: =IFERROR(G24/$G$33,0) -> 0.00024088765 | I24: 递延资产
A25: 2.17 | B25: 其他（预留） | F25: 0 | G25: =SUM(C25:F25) -> 0 | H25: =IFERROR(G25/$G$33,0) -> 0 | I25: 固定资产
A26: 三 | B26: 第三部分 预备费 | F26: =F27+F28 -> 5829.3812 | G26: =SUM(C26:F26) -> 5829.3812 | H26: =IFERROR(G26/$G$33,0) -> 0.046807532
A27: 3.1 | B27: 基本预备费 | F27: =(G5+G8)*0_参数!$C$121 -> 5829.3812 | G27: =SUM(C27:F27) -> 5829.3812 | H27: =IFERROR(G27/$G$33,0) -> 0.046807532 | I27: 固定资产
A28: 3.2 | B28: 涨价预备费 | F28: =(G5+G8)*0_参数!$C$122 -> 0 | G28: =SUM(C28:F28) -> 0 | H28: =IFERROR(G28/$G$33,0) -> 0 | I28: 固定资产
A29: 四 | B29: 工程建设投资（建设投资）= 一 + 二 + 三 | C29: =C5 -> 1891.8 | D29: =D5 -> 920 | E29: =E5 -> 107652 | F29: =F8+F26 -> 11953.206 | G29: =SUM(C29:F29) -> 122417.01 | H29: =IFERROR(G29/$G$33,0) -> 0.98295818
A30: 五 | B30: 建设期利息 | F30: =11_还本付息!$V$9 -> 1536.2551 | G30: =SUM(C30:F30) -> 1536.2551 | H30: =IFERROR(G30/$G$33,0) -> 0.012335496 | I30: 固定资产（资本化）
A31: 六 | B31: 固定资产投资 = 四 + 五 | C31: =C29 -> 1891.8 | D31: =D29 -> 920 | E31: =E29 -> 107652 | F31: =F29+F30 -> 13489.461 | G31: =SUM(C31:F31) -> 123953.26 | H31: =IFERROR(G31/$G$33,0) -> 0.99529368
A32: 七 | B32: 铺底流动资金 | F32: =2_流动资金!$V$16 -> 586.12245 | G32: =SUM(C32:F32) -> 586.12245 | H32: =IFERROR(G32/$G$33,0) -> 0.0047063221 | I32: ＝ 正常年流动资金 × (1 − 借款比例)
A33: 八 | B33: 项目总投资 = 六 + 七 | C33: =C31 -> 1891.8 | D33: =D31 -> 920 | E33: =E31 -> 107652 | F33: =F31+F32 -> 14075.584 | G33: =SUM(C33:F33) -> 124539.38 | H33: =IFERROR(G33/$G$33,0) -> 1
B34: 构成比例 | C34: =IFERROR(C33/G33,0) -> 0.015190375 | D34: =IFERROR(D33/G33,0) -> 0.0073872214 | E34: =IFERROR(E33/G33,0) -> 0.86440126 | F34: =IFERROR(F33/G33,0) -> 0.11302114
B36: 辅助计算（供附表 5 / 6 使用）
B37: 可抵扣进项税-设备 | F37: =IF(0_参数!$C$77=1,$E$6/(1+0_参数!$C$81)*0_参数!$C$81,0) -> 12384.743
B38: 可抵扣进项税-建安 | F38: =IF(0_参数!$C$77=1,($C$7+$D$7)/(1+0_参数!$C$80)*0_参数!$C$80,0) -> 232.16697
B39: 可抵扣进项税合计（运营期初留抵） | F39: =F37+F38 -> 12616.91
B40: 其他费用中计入固定资产部分 | F40: =SUMIF(I9:I25,"固定资产",F9:F25) -> 6081.5248
B41: 其他费用中计入递延资产部分 | F41: =SUMIF(I9:I25,"递延资产",F9:F25) -> 42.3
B42: 算力设备直接费（含税） | F42: ='1-2_设备及软件'!$F$12 -> 94250
...

Sheet 1-1_建安工程费
A1: 附表 1-1 建筑安装工程费用估算表
A2: 单位：万元（人民币，含税）。MDC 项目建安只剩配套用房、模块基础、场地、管廊、外线
A4: 序号 | B4: 工程名称 | C4: 数量 | D4: 单位 | E4: 单价（万元） | F4: 类型 | G4: 建筑工程 | H4: 安装工程 | I4: 合计 | J4: 备注
A5: 1 | B5: 配套运维用房 土建（含装饰） | C5: =0_参数!$C$30 -> 1500 | D5: ㎡ | E5: 0.45 | F5: 建筑 | G5: =IF(F5="建筑",C5*E5,0) -> 675 | H5: =IF(F5="安装",C5*E5,0) -> 0 | I5: =G5+H5 -> 675 | J5: 面积联动参数 C2；示例 4500 元/㎡
A6: 2 | B6: 配套运维用房 机电安装（给排水/电/暖通/弱电/消防） | C6: =0_参数!$C$30 -> 1500 | D6: ㎡ | E6: 0.08 | F6: 安装 | G6: =IF(F6="建筑",C6*E6,0) -> 0 | H6: =IF(F6="安装",C6*E6,0) -> 120 | I6: =G6+H6 -> 120 | J6: 示例 800 元/㎡
A7: 3 | B7: 柴发房 | C7: 310 | D7: ㎡ | E7: 0.28 | F7: 建筑 | G7: =IF(F7="建筑",C7*E7,0) -> 86.8 | H7: =IF(F7="安装",C7*E7,0) -> 0 | I7: =G7+H7 -> 86.8 | J7: 示例
A8: 4 | B8: 模块基础 / 钢平台 | C8: =0_参数!$C$18 -> 4 | D8: 套 | E8: 80 | F8: 建筑 | G8: =IF(F8="建筑",C8*E8,0) -> 320 | H8: =IF(F8="安装",C8*E8,0) -> 0 | I8: =G8+H8 -> 320 | J8: 按模块满载重量与冻深设计；数量联动 B1
A9: 5 | B9: 电力舱、冷源模块基础 | C9: 6 | D9: 座 | E9: 25 | F9: 建筑 | G9: =IF(F9="建筑",C9*E9,0) -> 150 | H9: =IF(F9="安装",C9*E9,0) -> 0 | I9: =G9+H9 -> 150 | J9: 示例
A10: 6 | B10: 场地道路与硬化（含吊装场地） | C10: 8000 | D10: ㎡ | E10: 0.018 | F10: 建筑 | G10: =IF(F10="建筑",C10*E10,0) -> 144 | H10: =IF(F10="安装",C10*E10,0) -> 0 | I10: =G10+H10 -> 144 | J10: 示例 180 元/㎡
A11: 7 | B11: 综合管廊 / 管线 | C11: 280 | D11: m | E11: 0.2 | F11: 建筑 | G11: =IF(F11="建筑",C11*E11,0) -> 56 | H11: =IF(F11="安装",C11*E11,0) -> 0 | I11: =G11+H11 -> 56 | J11: 示例 2000 元/m
A12: 8 | B12: 外线接入工程（10kV/35kV 线路、开关站） | C12: 1 | D12: 项 | E12: 800 | F12: 安装 | G12: =IF(F12="建筑",C12*E12,0) -> 0 | H12: =IF(F12="安装",C12*E12,0) -> 800 | I12: =G12+H12 -> 800 | J12: 按供电方案；常为关键路径
A13: 9 | B13: 消防水池、泵房及室外消防 | C13: 1 | D13: 项 | E13: 300 | F13: 建筑 | G13: =IF(F13="建筑",C13*E13,0) -> 300 | H13: =IF(F13="安装",C13*E13,0) -> 0 | I13: =G13+H13 -> 300 | J13: 可与海绵调蓄合建
A14: 10 | B14: 海绵城市设施（透水铺装、调蓄） | C14: 1 | D14: 项 | E14: 100 | F14: 建筑 | G14: =IF(F14="建筑",C14*E14,0) -> 100 | H14: =IF(F14="安装",C14*E14,0) -> 0 | I14: =G14+H14 -> 100 | J14: 按地方专项规划要求
A15: 11 | B15: 围墙、大门、绿化 | C15: 1 | D15: 项 | E15: 60 | F15: 建筑 | G15: =IF(F15="建筑",C15*E15,0) -> 60 | H15: =IF(F15="安装",C15*E15,0) -> 0 | I15: =G15+H15 -> 60 | J15: 示例
B16: 建安工程合计 | G16: =SUM(G5:G15) -> 1891.8 | H16: =SUM(H5:H15) -> 920 | I16: =G16+H16 -> 2811.8

Sheet 1-2_设备及软件
A1: 附表 1-2 设备及软件工程投资估算表
A2: 单位：万元（人民币，含税）。A 块价格由业主/算力运营方提供（黄底），B 块为我方基础设施口径。金额 = 数量 × 单价 × 敏感性系数
A4: 序号 | B4: 设备名称 | C4: 单位 | D4: 数量 | E4: 单价（万元，含税） | F4: 金额（万元） | G4: 资产类别 | H4: 来源 / 备注
A5: A | B5: 算力设备（价格：业主提供）
A6: A1 | B6: GPU 服务器（8 卡） | C6: 台 | D6: =0_参数!$C$23 -> 168 | E6: 450 | F6: =D6*E6*0_参数!$C$50 -> 75600 | G6: 算力设备 | H6: 【业主提供】业主采购意向/报价单；数量联动参数 B6
A7: A2 | B7: 算力网络设备（IB/RoCE 交换机、线缆） | C7: 套 | D7: 1 | E7: 800 | F7: =D7*E7*0_参数!$C$50 -> 800 | G7: 算力设备 | H7: 【业主提供】业主提供
A8: A3 | B8: 存储设备（全闪 + 海量） | C8: 套 | D8: 1 | E8: 500 | F8: =D8*E8*0_参数!$C$50 -> 500 | G8: 算力设备 | H8: 【业主提供】业主提供
A9: A4 | B9: 安全设备（含等保测评） | C9: 套 | D9: 1 | E9: 150 | F9: =D9*E9*0_参数!$C$50 -> 150 | G9: 算力设备 | H9: 【业主提供】业主提供
A10: A5 | B10: 计算平台软件 | C10: 套 | D10: 1 | E10: 12000 | F10: =D10*E10*0_参数!$C$50 -> 12000 | G10: 算力设备 | H10: 【业主提供】业主提供；软件维护费按此项 × 费率
A11: A6 | B11: 系统集成与过程管理 | C11: 套 | D11: 1 | E11: 5200 | F11: =D11*E11*0_参数!$C$50 -> 5200 | G11: 算力设备 | H11: 【业主提供】业主提供
B12: A 小计 算力设备 | F12: =SUM(F6:F11) -> 94250
A14: B | B14: 基础设施设备（我方口径）
A15: B1 | B15: 模块化算力单元（含内部配电、冷却分配、监控） | C15: 套 | D15: =0_参数!$C$18 -> 4 | E15: 1800 | F15: =D15*E15*0_参数!$C$51 -> 7200 | G15: 基础设施设备 | H15: 数量联动参数 B1；单价为我方概算口径（示例）
A16: B2 | B16: 预制式电力舱（中压/变配电/低压） | C16: 套 | D16: 2 | E16: 600 | F16: =D16*E16*0_参数!$C$51 -> 1200 | G16: 基础设施设备 | H16: 示例
A17: B3 | B17: 一体化外部冷源模块（工厂 FAT） | C17: 套 | D17: 4 | E17: 300 | F17: =D17*E17*0_参数!$C$51 -> 1200 | G17: 基础设施设备 | H17: 示例
A18: B4 | B18: UPS 系统（含电池） | C18: 套 | D18: 12 | E18: 135 | F18: =D18*E18*0_参数!$C$51 -> 1620 | G18: 基础设施设备 | H18: 如采用 BESS 路线在此替换
A19: B5 | B19: 柴油发电机组 | C19: 台 | D19: 3 | E19: 220 | F19: =D19*E19*0_参数!$C$51 -> 660 | G19: 基础设施设备 | H19: 是否配置走等级论证（P 系列）
A20: B6 | B20: DCIM / 弱电智能化 / 安防 | C20: 套 | D20: 1 | E20: 1100 | F20: =D20*E20*0_参数!$C$51 -> 1100 | G20: 基础设施设备 | H20: 示例
A21: B7 | B21: 机柜及其他配套 | C21: 套 | D21: 1 | E21: 422 | F21: =D21*E21*0_参数!$C$51 -> 422 | G21: 基础设施设备 | H21: 示例
B22: B 小计 基础设施设备 | F22: =SUM(F15:F21) -> 13402
B23: 设备及软件工程合计 | F23: ='1-2_设备及软件'!$F$12+'1-2_设备及软件'!$F$22 -> 107652
B25: 注：可研正文设备方案只写通用工程口径（单模块 IT 功率、冷却方式、外形/重量）；产品商品名与型号只在本表出现一次。

Sheet 2_流动资金
A1: 附表 2 流动资金估算表（分项详细估算法）
A2: 单位：万元。周转次数 = 360 / 周转天数；铺底流动资金 = 正常年流动资金 × (1 − 流动资金借款比例)
A3: 序号 | B3: 项目 \ 年份 | C3: 单位/说明 | D3: 1 | E3: =D3+1 -> 2 | F3: =E3+1 -> 3 | G3: =F3+1 -> 4 | H3: =G3+1 -> 5 | I3: =H3+1 -> 6 | J3: =I3+1 -> 7 | K3: =J3+1 -> 8 | L3: =K3+1 -> 9 | ... U3: =T3+1 -> 18 | V3: 合计/平均
B4: 阶段 | D4: =IF(D$3<=0_参数!$C$9,"建设",IF(D$3<=0_参数!$C$9+0_参数!$C$10,"运营","")) -> 建设 | E4: =IF(E$3<=0_参数!$C$9,"建设",IF(E$3<=0_参数!$C$9+0_参数!$C$10,"运营","")) -> 运营 | F4: =IF(F$3<=0_参数!$C$9,"建设",IF(F$3<=0_参数!$C$9+0_参数!$C$10,"运营","")) -> 运营 | G4: =IF(G$3<=0_参数!$C$9,"建设",IF(G$3<=0_参数!$C$9+0_参数!$C$10,"运营","")) -> 运营 | H4: =IF(H$3<=0_参数!$C$9,"建设",IF(H$3<=0_参数!$C$9+0_参数!$C$10,"运营","")) -> 运营 | I4: =IF(I$3<=0_参数!$C$9,"建设",IF(I$3<=0_参数!$C$9+0_参数!$C$10,"运营","")) -> 运营 | J4: =IF(J$3<=0_参数!$C$9,"建设",IF(J$3<=0_参数!$C$9+0_参数!$C$10,"运营","")) -> 运营 | K4: =IF(K$3<=0_参数!$C$9,"建设",IF(K$3<=0_参数!$C$9+0_参数!$C$10,"运营","")) -> 运营 | ... U4: =IF(U$3<=0_参数!$C$9,"建设",IF(U$3<=0_参数!$C$9+0_参数!$C$10,"运营",""))
B5: 运营年序号 | D5: =IF(D$4="运营",D$3-0_参数!$C$9,0) -> 0 | E5: =IF(E$4="运营",E$3-0_参数!$C$9,0) -> 1 | F5: =IF(F$4="运营",F$3-0_参数!$C$9,0) -> 2 | G5: =IF(G$4="运营",G$3-0_参数!$C$9,0) -> 3 | H5: =IF(H$4="运营",H$3-0_参数!$C$9,0) -> 4 | I5: =IF(I$4="运营",I$3-0_参数!$C$9,0) -> 5 | J5: =IF(J$4="运营",J$3-0_参数!$C$9,0) -> 6 | K5: =IF(K$4="运营",K$3-0_参数!$C$9,0) -> 7 | ... U5: =IF(U$4="运营",U$3-0_参数!$C$9,0) -> 0
B6: 建设年序号 | D6: =IF(D$4="建设",D$3,0) -> 1 | E6: =IF(E$4="建设",E$3,0) -> 0 | F6: =IF(F$4="建设",F$3,0) -> 0 | G6: =IF(G$4="建设",G$3,0) -> 0 | H6: =IF(H$4="建设",H$3,0) -> 0 | I6: =IF(I$4="建设",I$3,0) -> 0 | J6: =IF(J$4="建设",J$3,0) -> 0 | K6: =IF(K$4="建设",K$3,0) -> 0 | ... U6: =IF(U$4="建设",U$3,0) -> 0
A7: 1.1 | B7: 应收账款 | C7: 万元 | D7: =IF(D$4="运营",6_收入税金!D$11/(0_参数!$C$101/0_参数!$C$97),0) -> 0 | E7: =IF(E$4="运营",6_收入税金!E$11/(0_参数!$C$101/0_参数!$C$97),0) -> 1775.0943 | F7: =IF(F$4="运营",6_收入税金!F$11/(0_参数!$C$101/0_参数!$C$97),0) -> 1996.9811 | G7: =IF(G$4="运营",6_收入税金!G$11/(0_参数!$C$101/0_参数!$C$97),0) -> 1996.9811 | H7: =IF(H$4="运营",6_收入税金!H$11/(0_参数!$C$101/0_参数!$C$97),0) -> 1996.9811 | I7: =IF(I$4="运营",6_收入税金!I$11/(0_参数!$C$101/0_参数!$C$97),0) -> 1996.9811 | J7: =IF(J$4="运营",6_收入税金!J$11/(0_参数!$C$101/0_参数!$C$97),0) -> 1996.9811 | K7: =IF(K$4="运营",6_收入税金!K$11/(0_参数!$C$101/0_参数!$C$97),0) -> 1996.9811 | ... U7: =IF(U$4="运营",6_收入税金!U$11/(0_参数!$C$101/0_参数!$C$97),0) -> 0
A8: 1.2 | B8: 存货（外购燃料动力） | C8: 万元 | D8: =IF(D$4="运营",4_总成本费用!D$16/(0_参数!$C$101/0_参数!$C$98),0) -> 0 | E8: =IF(E$4="运营",4_总成本费用!E$16/(0_参数!$C$101/0_参数!$C$98),0) -> 53.498705 | F8: =IF(F$4="运营",4_总成本费用!F$16/(0_参数!$C$101/0_参数!$C$98),0) -> 60.019122 | G8: =IF(G$4="运营",4_总成本费用!G$16/(0_参数!$C$101/0_参数!$C$98),0) -> 60.019122 | H8: =IF(H$4="运营",4_总成本费用!H$16/(0_参数!$C$101/0_参数!$C$98),0) -> 60.019122 | I8: =IF(I$4="运营",4_总成本费用!I$16/(0_参数!$C$101/0_参数!$C$98),0) -> 60.019122 | J8: =IF(J$4="运营",4_总成本费用!J$16/(0_参数!$C$101/0_参数!$C$98),0) -> 60.019122 | K8: =IF(K$4="运营",4_总成本费用!K$16/(0_参数!$C$101/0_参数!$C$98),0) -> 60.019122 | ... U8: =IF(U$4="运营",4_总成本费用!U$16/(0_参数!$C$101/0_参数!$C$98),0) -> 0
A9: 1.3 | B9: 现金（工资 + 其他管理费） | C9: 万元 | D9: =IF(D$4="运营",(4_总成本费用!D$17+4_总成本费用!D$22)/(0_参数!$C$101/0_参数!$C$99),0) -> 0 | E9: =IF(E$4="运营",(4_总成本费用!E$17+4_总成本费用!E$22)/(0_参数!$C$101/0_参数!$C$99),0) -> 51.1 | F9: =IF(F$4="运营",(4_总成本费用!F$17+4_总成本费用!F$22)/(0_参数!$C$101/0_参数!$C$99),0) -> 51.1 | G9: =IF(G$4="运营",(4_总成本费用!G$17+4_总成本费用!G$22)/(0_参数!$C$101/0_参数!$C$99),0) -> 51.1 | H9: =IF(H$4="运营",(4_总成本费用!H$17+4_总成本费用!H$22)/(0_参数!$C$101/0_参数!$C$99),0) -> 51.1 | I9: =IF(I$4="运营",(4_总成本费用!I$17+4_总成本费用!I$22)/(0_参数!$C$101/0_参数!$C$99),0) -> 51.1 | J9: =IF(J$4="运营",(4_总成本费用!J$17+4_总成本费用!J$22)/(0_参数!$C$101/0_参数!$C$99),0) -> 51.1 | K9: =IF(K$4="运营",(4_总成本费用!K$17+4_总成本费用!K$22)/(0_参数!$C$101/0_参数!$C$99),0) -> 51.1 | ... U9: =IF(U$4="运营",(4_总成本费用!U$17+4_总成本费用!U$22)/(0_参数!$C$101/0_参数!$C$99),0) -> 0
A10: 1 | B10: 流动资产合计 | C10: 万元 | D10: =D7+D8+D9 -> 0 | E10: =E7+E8+E9 -> 1879.693 | F10: =F7+F8+F9 -> 2108.1003 | G10: =G7+G8+G9 -> 2108.1003 | H10: =H7+H8+H9 -> 2108.1003 | I10: =I7+I8+I9 -> 2108.1003 | J10: =J7+J8+J9 -> 2108.1003 | K10: =K7+K8+K9 -> 2108.1003 | ... U10: =U7+U8+U9 -> 0
A11: 2.1 | B11: 应付账款（燃料动力 + 专线 + 外包） | C11: 万元 | D11: =IF(D$4="运营",(4_总成本费用!D$16+4_总成本费用!D$13+4_总成本费用!D$18)/(0_参数!$C$101/0_参数!$C$100),0) -> 0 | E11: =IF(E$4="运营",(4_总成本费用!E$16+4_总成本费用!E$13+4_总成本费用!E$18)/(0_参数!$C$101/0_参数!$C$100),0) -> 147.83833 | F11: =IF(F$4="运营",(4_总成本费用!F$16+4_总成本费用!F$13+4_总成本费用!F$18)/(0_参数!$C$101/0_参数!$C$100),0) -> 154.35874 | G11: =IF(G$4="运营",(4_总成本费用!G$16+4_总成本费用!G$13+4_总成本费用!G$18)/(0_参数!$C$101/0_参数!$C$100),0) -> 154.35874 | H11: =IF(H$4="运营",(4_总成本费用!H$16+4_总成本费用!H$13+4_总成本费用!H$18)/(0_参数!$C$101/0_参数!$C$100),0) -> 154.35874 | I11: =IF(I$4="运营",(4_总成本费用!I$16+4_总成本费用!I$13+4_总成本费用!I$18)/(0_参数!$C$101/0_参数!$C$100),0) -> 154.35874 | J11: =IF(J$4="运营",(4_总成本费用!J$16+4_总成本费用!J$13+4_总成本费用!J$18)/(0_参数!$C$101/0_参数!$C$100),0) -> 154.35874 | K11: =IF(K$4="运营",(4_总成本费用!K$16+4_总成本费用!K$13+4_总成本费用!K$18)/(0_参数!$C$101/0_参数!$C$100),0) -> 154.35874 | ... U11: =IF(U$4="运营",(4_总成本费用!U$16+4_总成本费用!U$13+4_总成本费用!U$18)/(0_参数!$C$101/0_参数!$C$100),0) -> 0
A12: 2 | B12: 流动负债合计 | C12: 万元 | D12: =D11 -> 0 | E12: =E11 -> 147.83833 | F12: =F11 -> 154.35874 | G12: =G11 -> 154.35874 | H12: =H11 -> 154.35874 | I12: =I11 -> 154.35874 | J12: =J11 -> 154.35874 | K12: =K11 -> 154.35874 | ... U12: =U11 -> 0
A13: 3 | B13: 流动资金 = 1 − 2 | C13: 万元 | D13: =D10-D12 -> 0 | E13: =E10-E12 -> 1731.8547 | F13: =F10-F12 -> 1953.7415 | G13: =G10-G12 -> 1953.7415 | H13: =H10-H12 -> 1953.7415 | I13: =I10-I12 -> 1953.7415 | J13: =J10-J12 -> 1953.7415 | K13: =K10-K12 -> 1953.7415 | ... U13: =U10-U12 -> 0
A14: 4 | B14: 流动资金本年增加额 | C14: 万元 | D14: =IF(D$4="运营",D13,0) -> 0 | E14: =IF(E$4="运营",E13-IF(1=0,0,D13),0) -> 1731.8547 | F14: =IF(F$4="运营",F13-IF(2=0,0,E13),0) -> 221.88679 | G14: =IF(G$4="运营",G13-IF(3=0,0,F13),0) -> 0 | H14: =IF(H$4="运营",H13-IF(4=0,0,G13),0) -> 0 | I14: =IF(I$4="运营",I13-IF(5=0,0,H13),0) -> 0 | J14: =IF(J$4="运营",J13-IF(6=0,0,I13),0) -> 0 | K14: =IF(K$4="运营",K13-IF(7=0,0,J13),0) -> 0 | L14: =IF(L$4="运营",L13-IF(8=0,0,K13),0) -> 0 | M14: =IF(M$4="运营",M13-IF(9=0,0,L13),0) -> 0 | N14: =IF(N$4="运营",N13-IF(10=0,0,M13),0) -> 0 | O14: =IF(O$4="运营",O13-IF(11=0,0,N13),0) -> 0 | P14: =IF(P$4="运营",P13-IF(12=0,0,O13),0) -> 0 | Q14: =IF(Q$4="运营",Q13-IF(13=0,0,P13),0) -> 0 | R14: =IF(R$4="运营",R13-IF(14=0,0,Q13),0) -> 0 | S14: =IF(S$4="运营",S13-IF(15=0,0,R13),0) -> 0 | T14: =IF(T$4="运营",T13-IF(16=0,0,S13),0) -> 0 | U14: =IF(U$4="运营",U13-IF(17=0,0,T13),0) -> 0 | V14: =SUM(D14:U14) -> 1953.7415
B15: 正常年流动资金 = 运营第 A10 年 | V15: =INDEX(D13:U13,0_参数!$C$9+0_参数!$C$15) -> 1953.7415
B16: 铺底流动资金 = 正常年流动资金 × (1 − 借款比例) | V16: =V15*(1-0_参数!$C$93) -> 586.12245
A17: 5 | B17: 流动资金借款本年增加 | C17: 万元 | D17: =D14*0_参数!$C$93 -> 0 | E17: =E14*0_参数!$C$93 -> 1212.2983 | F17: =F14*0_参数!$C$93 -> 155.32075 | G17: =G14*0_参数!$C$93 -> 0 | H17: =H14*0_参数!$C$93 -> 0 | I17: =I14*0_参数!$C$93 -> 0 | J17: =J14*0_参数!$C$93 -> 0 | K17: =K14*0_参数!$C$93 -> 0 | ... U17: =U14*0_参数!$C$93 -> 0 | V17: =SUM(D17:U17) -> 1367.6191
A18: 6 | B18: 流动资金自有资金本年增加 | C18: 万元 | D18: =D14*(1-0_参数!$C$93) -> 0 | E18: =E14*(1-0_参数!$C$93) -> 519.55642 | F18: =F14*(1-0_参数!$C$93) -> 66.566038 | G18: =G14*(1-0_参数!$C$93) -> 0 | H18: =H14*(1-0_参数!$C$93) -> 0 | I18: =I14*(1-0_参数!$C$93) -> 0 | J18: =J14*(1-0_参数!$C$93) -> 0 | K18: =K14*(1-0_参数!$C$93) -> 0 | ... U18: =U14*(1-0_参数!$C$93) -> 0 | V18: =SUM(D18:U18) -> 586.12245
A19: 7 | B19: 计算期末回收流动资金（供附表 8） | C19: 万元 | D19: =IF(D$3=0_参数!$C$9+0_参数!$C$10,D13,0) -> 0 | E19: =IF(E$3=0_参数!$C$9+0_参数!$C$10,E13,0) -> 0 | F19: =IF(F$3=0_参数!$C$9+0_参数!$C$10,F13,0) -> 0 | G19: =IF(G$3=0_参数!$C$9+0_参数!$C$10,G13,0) -> 0 | H19: =IF(H$3=0_参数!$C$9+0_参数!$C$10,H13,0) -> 0 | I19: =IF(I$3=0_参数!$C$9+0_参数!$C$10,I13,0) -> 0 | J19: =IF(J$3=0_参数!$C$9+0_参数!$C$10,J13,0) -> 0 | K19: =IF(K$3=0_参数!$C$9+0_参数!$C$10,K13,0) -> 0 | ... U19: =IF(U$3=0_参数!$C$9+0_参数!$C$10,U13,0) -> 0 | V19: =SUM(D19:U19) -> 1953.7415

Sheet 3_资金筹措
A1: 附表 3 投资使用计划与资金筹措表
A2: 单位：万元。建设投资按参数 A6–A8 比例分年投入；资本金优先用于建设投资，其余为长期借款
A3: 序号 | B3: 项目 \ 年份 | C3: 单位/说明 | D3: 1 | E3: =D3+1 -> 2 | F3: =E3+1 -> 3 | G3: =F3+1 -> 4 | H3: =G3+1 -> 5 | I3: =H3+1 -> 6 | J3: =I3+1 -> 7 | K3: =J3+1 -> 8 | L3: =K3+1 -> 9 | ... U3: =T3+1 -> 18 | V3: 合计/平均
B4: 阶段 | D4: =IF(D$3<=0_参数!$C$9,"建设",IF(D$3<=0_参数!$C$9+0_参数!$C$10,"运营","")) -> 建设 | E4: =IF(E$3<=0_参数!$C$9,"建设",IF(E$3<=0_参数!$C$9+0_参数!$C$10,"运营","")) -> 运营 | F4: =IF(F$3<=0_参数!$C$9,"建设",IF(F$3<=0_参数!$C$9+0_参数!$C$10,"运营","")) -> 运营 | G4: =IF(G$3<=0_参数!$C$9,"建设",IF(G$3<=0_参数!$C$9+0_参数!$C$10,"运营","")) -> 运营 | H4: =IF(H$3<=0_参数!$C$9,"建设",IF(H$3<=0_参数!$C$9+0_参数!$C$10,"运营","")) -> 运营 | I4: =IF(I$3<=0_参数!$C$9,"建设",IF(I$3<=0_参数!$C$9+0_参数!$C$10,"运营","")) -> 运营 | J4: =IF(J$3<=0_参数!$C$9,"建设",IF(J$3<=0_参数!$C$9+0_参数!$C$10,"运营","")) -> 运营 | K4: =IF(K$3<=0_参数!$C$9,"建设",IF(K$3<=0_参数!$C$9+0_参数!$C$10,"运营","")) -> 运营 | ... U4: =IF(U$3<=0_参数!$C$9,"建设",IF(U$3<=0_参数!$C$9+0_参数!$C$10,"运营",""))
B5: 运营年序号 | D5: =IF(D$4="运营",D$3-0_参数!$C$9,0) -> 0 | E5: =IF(E$4="运营",E$3-0_参数!$C$9,0) -> 1 | F5: =IF(F$4="运营",F$3-0_参数!$C$9,0) -> 2 | G5: =IF(G$4="运营",G$3-0_参数!$C$9,0) -> 3 | H5: =IF(H$4="运营",H$3-0_参数!$C$9,0) -> 4 | I5: =IF(I$4="运营",I$3-0_参数!$C$9,0) -> 5 | J5: =IF(J$4="运营",J$3-0_参数!$C$9,0) -> 6 | K5: =IF(K$4="运营",K$3-0_参数!$C$9,0) -> 7 | ... U5: =IF(U$4="运营",U$3-0_参数!$C$9,0) -> 0
B6: 建设年序号 | D6: =IF(D$4="建设",D$3,0) -> 1 | E6: =IF(E$4="建设",E$3,0) -> 0 | F6: =IF(F$4="建设",F$3,0) -> 0 | G6: =IF(G$4="建设",G$3,0) -> 0 | H6: =IF(H$4="建设",H$3,0) -> 0 | I6: =IF(I$4="建设",I$3,0) -> 0 | J6: =IF(J$4="建设",J$3,0) -> 0 | K6: =IF(K$4="建设",K$3,0) -> 0 | ... U6: =IF(U$4="建设",U$3,0) -> 0
B7: 建设投资年投入比例 | D7: =IF(D$6=1,0_参数!$C$11,IF(D$6=2,0_参数!$C$12,IF(D$6=3,0_参数!$C$13,0))) -> 1 | E7: =IF(E$6=1,0_参数!$C$11,IF(E$6=2,0_参数!$C$12,IF(E$6=3,0_参数!$C$13,0))) -> 0 | F7: =IF(F$6=1,0_参数!$C$11,IF(F$6=2,0_参数!$C$12,IF(F$6=3,0_参数!$C$13,0))) -> 0 | G7: =IF(G$6=1,0_参数!$C$11,IF(G$6=2,0_参数!$C$12,IF(G$6=3,0_参数!$C$13,0))) -> 0 | H7: =IF(H$6=1,0_参数!$C$11,IF(H$6=2,0_参数!$C$12,IF(H$6=3,0_参数!$C$13,0))) -> 0 | I7: =IF(I$6=1,0_参数!$C$11,IF(I$6=2,0_参数!$C$12,IF(I$6=3,0_参数!$C$13,0))) -> 0 | J7: =IF(J$6=1,0_参数!$C$11,IF(J$6=2,0_参数!$C$12,IF(J$6=3,0_参数!$C$13,0))) -> 0 | K7: =IF(K$6=1,0_参数!$C$11,IF(K$6=2,0_参数!$C$12,IF(K$6=3,0_参数!$C$13,0))) -> 0 | ... U7: =IF(U$6=1,0_参数!$C$11,IF(U$6=2,0_参数!$C$12,IF(U$6=3,0_参数!$C$13,0))) -> 0 | V7: =SUM(D7:U7) -> 1
A8: 1.1 | B8: 建设投资 | C8: 万元 | D8: =1_总投资估算!$G$29*D7 -> 122417.01 | E8: =1_总投资估算!$G$29*E7 -> 0 | F8: =1_总投资估算!$G$29*F7 -> 0 | G8: =1_总投资估算!$G$29*G7 -> 0 | H8: =1_总投资估算!$G$29*H7 -> 0 | I8: =1_总投资估算!$G$29*I7 -> 0 | J8: =1_总投资估算!$G$29*J7 -> 0 | K8: =1_总投资估算!$G$29*K7 -> 0 | ... U8: =1_总投资估算!$G$29*U7 -> 0 | V8: =SUM(D8:U8) -> 122417.01
A9: 1.2 | B9: 建设期借款利息 | C9: 万元 | D9: =11_还本付息!D$9 -> 1536.2551 | E9: =11_还本付息!E$9 -> 0 | F9: =11_还本付息!F$9 -> 0 | G9: =11_还本付息!G$9 -> 0 | H9: =11_还本付息!H$9 -> 0 | I9: =11_还本付息!I$9 -> 0 | J9: =11_还本付息!J$9 -> 0 | K9: =11_还本付息!K$9 -> 0 | ... U9: =11_还本付息!U$9 -> 0 | V9: =SUM(D9:U9) -> 1536.2551
A10: 1.3 | B10: 新增流动资金 | C10: 万元 | D10: =2_流动资金!D$14 -> 0 | E10: =2_流动资金!E$14 -> 1731.8547 | F10: =2_流动资金!F$14 -> 221.88679 | G10: =2_流动资金!G$14 -> 0 | H10: =2_流动资金!H$14 -> 0 | I10: =2_流动资金!I$14 -> 0 | J10: =2_流动资金!J$14 -> 0 | K10: =2_流动资金!K$14 -> 0 | ... U10: =2_流动资金!U$14 -> 0 | V10: =SUM(D10:U10) -> 1953.7415
A11: 1 | B11: 总资金（含全部流动资金） | C11: 万元 | D11: =D8+D9+D10 -> 123953.26 | E11: =E8+E9+E10 -> 1731.8547 | F11: =F8+F9+F10 -> 221.88679 | G11: =G8+G9+G10 -> 0 | H11: =H8+H9+H10 -> 0 | I11: =I8+I9+I10 -> 0 | J11: =J8+J9+J10 -> 0 | K11: =K8+K9+K10 -> 0 | ... U11: =U8+U9+U10 -> 0 | V11: =SUM(D11:U11) -> 125907
A12: 2.1.1 | B12: 资本金-用于建设投资 | C12: 万元 | D12: =MIN(0_参数!$C$89,1_总投资估算!$G$29)*D7 -> 20000 | E12: =MIN(0_参数!$C$89,1_总投资估算!$G$29)*E7 -> 0 | F12: =MIN(0_参数!$C$89,1_总投资估算!$G$29)*F7 -> 0 | G12: =MIN(0_参数!$C$89,1_总投资估算!$G$29)*G7 -> 0 | H12: =MIN(0_参数!$C$89,1_总投资估算!$G$29)*H7 -> 0 | I12: =MIN(0_参数!$C$89,1_总投资估算!$G$29)*I7 -> 0 | J12: =MIN(0_参数!$C$89,1_总投资估算!$G$29)*J7 -> 0 | K12: =MIN(0_参数!$C$89,1_总投资估算!$G$29)*K7 -> 0 | ... U12: =MIN(0_参数!$C$89,1_总投资估算!$G$29)*U7 -> 0 | V12: =SUM(D12:U12) -> 20000
A13: 2.1.2 | B13: 资本金-用于建设期利息 | C13: 万元 | D13: =IF(0_参数!$C$92=0,D9,0) -> 0 | E13: =IF(0_参数!$C$92=0,E9,0) -> 0 | F13: =IF(0_参数!$C$92=0,F9,0) -> 0 | G13: =IF(0_参数!$C$92=0,G9,0) -> 0 | H13: =IF(0_参数!$C$92=0,H9,0) -> 0 | I13: =IF(0_参数!$C$92=0,I9,0) -> 0 | J13: =IF(0_参数!$C$92=0,J9,0) -> 0 | K13: =IF(0_参数!$C$92=0,K9,0) -> 0 | ... U13: =IF(0_参数!$C$92=0,U9,0) -> 0 | V13: =SUM(D13:U13) -> 0
A14: 2.1.3 | B14: 资本金-用于流动资金 | C14: 万元 | D14: =2_流动资金!D$18 -> 0 | E14: =2_流动资金!E$18 -> 519.55642 | F14: =2_流动资金!F$18 -> 66.566038 | G14: =2_流动资金!G$18 -> 0 | H14: =2_流动资金!H$18 -> 0 | I14: =2_流动资金!I$18 -> 0 | J14: =2_流动资金!J$18 -> 0 | K14: =2_流动资金!K$18 -> 0 | ... U14: =2_流动资金!U$18 -> 0 | V14: =SUM(D14:U14) -> 586.12245
A15: 2.1 | B15: 企业自筹资本金 小计 | C15: 万元 | D15: =D12+D13+D14 -> 20000 | E15: =E12+E13+E14 -> 519.55642 | F15: =F12+F13+F14 -> 66.566038 | G15: =G12+G13+G14 -> 0 | H15: =H12+H13+H14 -> 0 | I15: =I12+I13+I14 -> 0 | J15: =J12+J13+J14 -> 0 | K15: =K12+K13+K14 -> 0 | ... U15: =U12+U13+U14 -> 0 | V15: =SUM(D15:U15) -> 20586.122
A16: 2.2.1 | B16: 长期借款（建设投资） | C16: 万元 | D16: =D8-D12 -> 102417.01 | E16: =E8-E12 -> 0 | F16: =F8-F12 -> 0 | G16: =G8-G12 -> 0 | H16: =H8-H12 -> 0 | I16: =I8-I12 -> 0 | J16: =J8-J12 -> 0 | K16: =K8-K12 -> 0 | ... U16: =U8-U12 -> 0 | V16: =SUM(D16:U16) -> 102417.01
A17: 2.2.2 | B17: 长期借款（资本化建设期利息） | C17: 万元 | D17: =IF(0_参数!$C$92=1,D9,0) -> 1536.2551 | E17: =IF(0_参数!$C$92=1,E9,0) -> 0 | F17: =IF(0_参数!$C$92=1,F9,0) -> 0 | G17: =IF(0_参数!$C$92=1,G9,0) -> 0 | H17: =IF(0_参数!$C$92=1,H9,0) -> 0 | I17: =IF(0_参数!$C$92=1,I9,0) -> 0 | J17: =IF(0_参数!$C$92=1,J9,0) -> 0 | K17: =IF(0_参数!$C$92=1,K9,0) -> 0 | ... U17: =IF(0_参数!$C$92=1,U9,0) -> 0 | V17: =SUM(D17:U17) -> 1536.2551
A18: 2.2.3 | B18: 流动资金借款 | C18: 万元 | D18: =2_流动资金!D$17 -> 0 | E18: =2_流动资金!E$17 -> 1212.2983 | F18: =2_流动资金!F$17 -> 155.32075 | G18: =2_流动资金!G$17 -> 0 | H18: =2_流动资金!H$17 -> 0 | I18: =2_流动资金!I$17 -> 0 | J18: =2_流动资金!J$17 -> 0 | K18: =2_流动资金!K$17 -> 0 | ... U18: =2_流动资金!U$17 -> 0 | V18: =SUM(D18:U18) -> 1367.6191
A19: 2.2 | B19: 债务资金 小计 | C19: 万元 | D19: =D16+D17+D18 -> 103953.26 | E19: =E16+E17+E18 -> 1212.2983 | F19: =F16+F17+F18 -> 155.32075 | G19: =G16+G17+G18 -> 0 | H19: =H16+H17+H18 -> 0 | I19: =I16+I17+I18 -> 0 | J19: =J16+J17+J18 -> 0 | K19: =K16+K17+K18 -> 0 | ... U19: =U16+U17+U18 -> 0 | V19: =SUM(D19:U19) -> 105320.88
A20: 2 | B20: 资金筹措合计 | C20: 万元 | D20: =D15+D19 -> 123953.26 | E20: =E15+E19 -> 1731.8547 | F20: =F15+F19 -> 221.88679 | G20: =G15+G19 -> 0 | H20: =H15+H19 -> 0 | I20: =I15+I19 -> 0 | J20: =J15+J19 -> 0 | K20: =K15+K19 -> 0 | ... U20: =U15+U19 -> 0 | V20: =SUM(D20:U20) -> 125907
B21: 校核：筹措 − 总资金（应为 0） | C21: 万元 | D21: =D20-D11 -> 0 | E21: =E20-E11 -> 0 | F21: =F20-F11 -> 0 | G21: =G20-G11 -> 0 | H21: =H20-H11 -> 0 | I21: =I20-I11 -> 0 | J21: =J20-J11 -> 0 | K21: =K20-K11 -> 0 | ... U21: =U20-U11 -> 0 | V21: =SUM(D21:U21) -> 0

Sheet 4_总成本费用
A1: 附表 4 总成本费用估算表
A2: 单位：万元（人民币，不含税；含税输入按参数税率还原）
A3: 序号 | B3: 项目 \ 年份 | C3: 单位/说明 | D3: 1 | E3: =D3+1 -> 2 | F3: =E3+1 -> 3 | G3: =F3+1 -> 4 | H3: =G3+1 -> 5 | I3: =H3+1 -> 6 | J3: =I3+1 -> 7 | K3: =J3+1 -> 8 | L3: =K3+1 -> 9 | ... U3: =T3+1 -> 18 | V3: 合计/平均
B4: 阶段 | D4: =IF(D$3<=0_参数!$C$9,"建设",IF(D$3<=0_参数!$C$9+0_参数!$C$10,"运营","")) -> 建设 | E4: =IF(E$3<=0_参数!$C$9,"建设",IF(E$3<=0_参数!$C$9+0_参数!$C$10,"运营","")) -> 运营 | F4: =IF(F$3<=0_参数!$C$9,"建设",IF(F$3<=0_参数!$C$9+0_参数!$C$10,"运营","")) -> 运营 | G4: =IF(G$3<=0_参数!$C$9,"建设",IF(G$3<=0_参数!$C$9+0_参数!$C$10,"运营","")) -> 运营 | H4: =IF(H$3<=0_参数!$C$9,"建设",IF(H$3<=0_参数!$C$9+0_参数!$C$10,"运营","")) -> 运营 | I4: =IF(I$3<=0_参数!$C$9,"建设",IF(I$3<=0_参数!$C$9+0_参数!$C$10,"运营","")) -> 运营 | J4: =IF(J$3<=0_参数!$C$9,"建设",IF(J$3<=0_参数!$C$9+0_参数!$C$10,"运营","")) -> 运营 | K4: =IF(K$3<=0_参数!$C$9,"建设",IF(K$3<=0_参数!$C$9+0_参数!$C$10,"运营","")) -> 运营 | ... U4: =IF(U$3<=0_参数!$C$9,"建设",IF(U$3<=0_参数!$C$9+0_参数!$C$10,"运营",""))
B5: 运营年序号 | D5: =IF(D$4="运营",D$3-0_参数!$C$9,0) -> 0 | E5: =IF(E$4="运营",E$3-0_参数!$C$9,0) -> 1 | F5: =IF(F$4="运营",F$3-0_参数!$C$9,0) -> 2 | G5: =IF(G$4="运营",G$3-0_参数!$C$9,0) -> 3 | H5: =IF(H$4="运营",H$3-0_参数!$C$9,0) -> 4 | I5: =IF(I$4="运营",I$3-0_参数!$C$9,0) -> 5 | J5: =IF(J$4="运营",J$3-0_参数!$C$9,0) -> 6 | K5: =IF(K$4="运营",K$3-0_参数!$C$9,0) -> 7 | ... U5: =IF(U$4="运营",U$3-0_参数!$C$9,0) -> 0
B6: 建设年序号 | D6: =IF(D$4="建设",D$3,0) -> 1 | E6: =IF(E$4="建设",E$3,0) -> 0 | F6: =IF(F$4="建设",F$3,0) -> 0 | G6: =IF(G$4="建设",G$3,0) -> 0 | H6: =IF(H$4="建设",H$3,0) -> 0 | I6: =IF(I$4="建设",I$3,0) -> 0 | J6: =IF(J$4="建设",J$3,0) -> 0 | K6: =IF(K$4="建设",K$3,0) -> 0 | ... U6: =IF(U$4="建设",U$3,0) -> 0
B7: 投产比例 | D7: =IF(D$5>0,INDEX(0_参数!$D$126:$R$126,D$5),0) -> 0 | E7: =IF(E$5>0,INDEX(0_参数!$D$126:$R$126,E$5),0) -> 1 | F7: =IF(F$5>0,INDEX(0_参数!$D$126:$R$126,F$5),0) -> 1 | G7: =IF(G$5>0,INDEX(0_参数!$D$126:$R$126,G$5),0) -> 1 | H7: =IF(H$5>0,INDEX(0_参数!$D$126:$R$126,H$5),0) -> 1 | I7: =IF(I$5>0,INDEX(0_参数!$D$126:$R$126,I$5),0) -> 1 | J7: =IF(J$5>0,INDEX(0_参数!$D$126:$R$126,J$5),0) -> 1 | K7: =IF(K$5>0,INDEX(0_参数!$D$126:$R$126,K$5),0) -> 1 | ... U7: =IF(U$5>0,INDEX(0_参数!$D$126:$R$126,U$5),0) -> 0
B8: 售卖比例（含敏感性） | D8: =MIN(1,IF(D$5>0,INDEX(0_参数!$D$127:$R$127,D$5),0)*0_参数!$C$48) -> 0 | E8: =MIN(1,IF(E$5>0,INDEX(0_参数!$D$127:$R$127,E$5),0)*0_参数!$C$48) -> 0.8 | F8: =MIN(1,IF(F$5>0,INDEX(0_参数!$D$127:$R$127,F$5),0)*0_参数!$C$48) -> 0.9 | G8: =MIN(1,IF(G$5>0,INDEX(0_参数!$D$127:$R$127,G$5),0)*0_参数!$C$48) -> 0.9 | H8: =MIN(1,IF(H$5>0,INDEX(0_参数!$D$127:$R$127,H$5),0)*0_参数!$C$48) -> 0.9 | I8: =MIN(1,IF(I$5>0,INDEX(0_参数!$D$127:$R$127,I$5),0)*0_参数!$C$48) -> 0.9 | J8: =MIN(1,IF(J$5>0,INDEX(0_参数!$D$127:$R$127,J$5),0)*0_参数!$C$48) -> 0.9 | K8: =MIN(1,IF(K$5>0,INDEX(0_参数!$D$127:$R$127,K$5),0)*0_参数!$C$48) -> 0.9 | ... U8: =MIN(1,IF(U$5>0,INDEX(0_参数!$D$127:$R$127,U$5),0)*0_参数!$C$48) -> 0
B9: IT 运行负载率 | D9: =IF(D$5>0,INDEX(0_参数!$D$128:$R$128,D$5),0) -> 0 | E9: =IF(E$5>0,INDEX(0_参数!$D$128:$R$128,E$5),0) -> 0.9 | F9: =IF(F$5>0,INDEX(0_参数!$D$128:$R$128,F$5),0) -> 0.9 | G9: =IF(G$5>0,INDEX(0_参数!$D$128:$R$128,G$5),0) -> 0.9 | H9: =IF(H$5>0,INDEX(0_参数!$D$128:$R$128,H$5),0) -> 0.9 | I9: =IF(I$5>0,INDEX(0_参数!$D$128:$R$128,I$5),0) -> 0.9 | J9: =IF(J$5>0,INDEX(0_参数!$D$128:$R$128,J$5),0) -> 0.9 | K9: =IF(K$5>0,INDEX(0_参数!$D$128:$R$128,K$5),0) -> 0.9 | ... U9: =IF(U$5>0,INDEX(0_参数!$D$128:$R$128,U$5),0) -> 0
B10: IT 年用电量 | C10: 万kWh | D10: =IF(D$4="运营",0_参数!$C$20*D7*D8*D9*0_参数!$C$36/10000,0) -> 0 | E10: =IF(E$4="运营",0_参数!$C$20*E7*E8*E9*0_参数!$C$36/10000,0) -> 1332.0806 | F10: =IF(F$4="运营",0_参数!$C$20*F7*F8*F9*0_参数!$C$36/10000,0) -> 1498.5907 | G10: =IF(G$4="运营",0_参数!$C$20*G7*G8*G9*0_参数!$C$36/10000,0) -> 1498.5907 | H10: =IF(H$4="运营",0_参数!$C$20*H7*H8*H9*0_参数!$C$36/10000,0) -> 1498.5907 | I10: =IF(I$4="运营",0_参数!$C$20*I7*I8*I9*0_参数!$C$36/10000,0) -> 1498.5907 | J10: =IF(J$4="运营",0_参数!$C$20*J7*J8*J9*0_参数!$C$36/10000,0) -> 1498.5907 | K10: =IF(K$4="运营",0_参数!$C$20*K7*K8*K9*0_参数!$C$36/10000,0) -> 1498.5907 | ... U10: =IF(U$4="运营",0_参数!$C$20*U7*U8*U9*0_参数!$C$36/10000,0) -> 0 | V10: =IFERROR(SUMIF(D$4:U$4,"运营",D10:U10)/0_参数!$C$10,0) -> 1481.9397
B11: 项目年总用电量 | C11: 万kWh | D11: =IF(D$4="运营",D10*0_参数!$C$29+0_参数!$C$32*0_参数!$C$35*0_参数!$C$36/10000,0) -> 0 | E11: =IF(E$4="运营",E10*0_参数!$C$29+0_参数!$C$32*0_参数!$C$35*0_参数!$C$36/10000,0) -> 1595.5072 | F11: =IF(F$4="运营",F10*0_参数!$C$29+0_参数!$C$32*0_参数!$C$35*0_参数!$C$36/10000,0) -> 1791.989 | G11: =IF(G$4="运营",G10*0_参数!$C$29+0_参数!$C$32*0_参数!$C$35*0_参数!$C$36/10000,0) -> 1791.989 | H11: =IF(H$4="运营",H10*0_参数!$C$29+0_参数!$C$32*0_参数!$C$35*0_参数!$C$36/10000,0) -> 1791.989 | I11: =IF(I$4="运营",I10*0_参数!$C$29+0_参数!$C$32*0_参数!$C$35*0_参数!$C$36/10000,0) -> 1791.989 | J11: =IF(J$4="运营",J10*0_参数!$C$29+0_参数!$C$32*0_参数!$C$35*0_参数!$C$36/10000,0) -> 1791.989 | K11: =IF(K$4="运营",K10*0_参数!$C$29+0_参数!$C$32*0_参数!$C$35*0_参数!$C$36/10000,0) -> 1791.989 | ... U11: =IF(U$4="运营",U10*0_参数!$C$29+0_参数!$C$32*0_参数!$C$35*0_参数!$C$36/10000,0) -> 0 | V11: =IFERROR(SUMIF(D$4:U$4,"运营",D11:U11)/0_参数!$C$10,0) -> 1772.3409
B12: 年用水量 | C12: m³ | D12: =IF(D$4="运营",0_参数!$C$37*D7,0) -> 0 | E12: =IF(E$4="运营",0_参数!$C$37*E7,0) -> 16000 | F12: =IF(F$4="运营",0_参数!$C$37*F7,0) -> 16000 | G12: =IF(G$4="运营",0_参数!$C$37*G7,0) -> 16000 | H12: =IF(H$4="运营",0_参数!$C$37*H7,0) -> 16000 | I12: =IF(I$4="运营",0_参数!$C$37*I7,0) -> 16000 | J12: =IF(J$4="运营",0_参数!$C$37*J7,0) -> 16000 | K12: =IF(K$4="运营",0_参数!$C$37*K7,0) -> 16000 | ... U12: =IF(U$4="运营",0_参数!$C$37*U7,0) -> 0 | V12: =IFERROR(SUMIF(D$4:U$4,"运营",D12:U12)/0_参数!$C$10,0) -> 16000
A13: 1 | B13: 专线及网络带宽费 | C13: 万元 | D13: =IF(D$4="运营",0_参数!$C$54*0_参数!$C$55/(1+0_参数!$C$56),0) -> 0 | E13: =IF(E$4="运营",0_参数!$C$54*0_参数!$C$55/(1+0_参数!$C$56),0) -> 566.03774 | F13: =IF(F$4="运营",0_参数!$C$54*0_参数!$C$55/(1+0_参数!$C$56),0) -> 566.03774 | G13: =IF(G$4="运营",0_参数!$C$54*0_参数!$C$55/(1+0_参数!$C$56),0) -> 566.03774 | H13: =IF(H$4="运营",0_参数!$C$54*0_参数!$C$55/(1+0_参数!$C$56),0) -> 566.03774 | I13: =IF(I$4="运营",0_参数!$C$54*0_参数!$C$55/(1+0_参数!$C$56),0) -> 566.03774 | J13: =IF(J$4="运营",0_参数!$C$54*0_参数!$C$55/(1+0_参数!$C$56),0) -> 566.03774 | K13: =IF(K$4="运营",0_参数!$C$54*0_参数!$C$55/(1+0_参数!$C$56),0) -> 566.03774 | ... U13: =IF(U$4="运营",0_参数!$C$54*0_参数!$C$55/(1+0_参数!$C$56),0) -> 0 | V13: =IFERROR(SUMIF(D$4:U$4,"运营",D13:U13)/0_参数!$C$10,0) -> 566.03774
A14: 2.1 | B14: 外购电力 | C14: 万元 | D14: =D11*0_参数!$C$38*0_参数!$C$49/(1+0_参数!$C$39) -> 0 | E14: =E11*0_参数!$C$38*0_参数!$C$49/(1+0_参数!$C$39) -> 635.37896 | F14: =F11*0_参数!$C$38*0_参数!$C$49/(1+0_参数!$C$39) -> 713.62396 | G14: =G11*0_参数!$C$38*0_参数!$C$49/(1+0_参数!$C$39) -> 713.62396 | H14: =H11*0_参数!$C$38*0_参数!$C$49/(1+0_参数!$C$39) -> 713.62396 | I14: =I11*0_参数!$C$38*0_参数!$C$49/(1+0_参数!$C$39) -> 713.62396 | J14: =J11*0_参数!$C$38*0_参数!$C$49/(1+0_参数!$C$39) -> 713.62396 | K14: =K11*0_参数!$C$38*0_参数!$C$49/(1+0_参数!$C$39) -> 713.62396 | ... U14: =U11*0_参数!$C$38*0_参数!$C$49/(1+0_参数!$C$39) -> 0 | V14: =IFERROR(SUMIF(D$4:U$4,"运营",D14:U14)/0_参数!$C$10,0) -> 705.79946
A15: 2.2 | B15: 外购水 | C15: 万元 | D15: =D12*0_参数!$C$40/(1+0_参数!$C$41)/10000 -> 0 | E15: =E12*0_参数!$C$40/(1+0_参数!$C$41)/10000 -> 6.6055046 | F15: =F12*0_参数!$C$40/(1+0_参数!$C$41)/10000 -> 6.6055046 | G15: =G12*0_参数!$C$40/(1+0_参数!$C$41)/10000 -> 6.6055046 | H15: =H12*0_参数!$C$40/(1+0_参数!$C$41)/10000 -> 6.6055046 | I15: =I12*0_参数!$C$40/(1+0_参数!$C$41)/10000 -> 6.6055046 | J15: =J12*0_参数!$C$40/(1+0_参数!$C$41)/10000 -> 6.6055046 | K15: =K12*0_参数!$C$40/(1+0_参数!$C$41)/10000 -> 6.6055046 | ... U15: =U12*0_参数!$C$40/(1+0_参数!$C$41)/10000 -> 0 | V15: =IFERROR(SUMIF(D$4:U$4,"运营",D15:U15)/0_参数!$C$10,0) -> 6.6055046
A16: 2 | B16: 外购燃料及动力 小计 | C16: 万元 | D16: =D14+D15 -> 0 | E16: =E14+E15 -> 641.98446 | F16: =F14+F15 -> 720.22946 | G16: =G14+G15 -> 720.22946 | H16: =H14+H15 -> 720.22946 | I16: =I14+I15 -> 720.22946 | J16: =J14+J15 -> 720.22946 | K16: =K14+K15 -> 720.22946 | ... U16: =U14+U15 -> 0 | V16: =IFERROR(SUMIF(D$4:U$4,"运营",D16:U16)/0_参数!$C$10,0) -> 712.40496
A17: 3 | B17: 工资及福利费 | C17: 万元 | D17: =IF(D$4="运营",0_参数!$C$68,0) -> 0 | E17: =IF(E$4="运营",0_参数!$C$68,0) -> 511 | F17: =IF(F$4="运营",0_参数!$C$68,0) -> 511 | G17: =IF(G$4="运营",0_参数!$C$68,0) -> 511 | H17: =IF(H$4="运营",0_参数!$C$68,0) -> 511 | I17: =IF(I$4="运营",0_参数!$C$68,0) -> 511 | J17: =IF(J$4="运营",0_参数!$C$68,0) -> 511 | K17: =IF(K$4="运营",0_参数!$C$68,0) -> 511 | ... U17: =IF(U$4="运营",0_参数!$C$68,0) -> 0 | V17: =IFERROR(SUMIF(D$4:U$4,"运营",D17:U17)/0_参数!$C$10,0) -> 511
A18: 4 | B18: 运维服务外包费 | C18: 万元 | D18: =IF(D$4="运营",0_参数!$C$57/(1+0_参数!$C$58),0) -> 0 | E18: =IF(E$4="运营",0_参数!$C$57/(1+0_参数!$C$58),0) -> 566.03774 | F18: =IF(F$4="运营",0_参数!$C$57/(1+0_参数!$C$58),0) -> 566.03774 | G18: =IF(G$4="运营",0_参数!$C$57/(1+0_参数!$C$58),0) -> 566.03774 | H18: =IF(H$4="运营",0_参数!$C$57/(1+0_参数!$C$58),0) -> 566.03774 | I18: =IF(I$4="运营",0_参数!$C$57/(1+0_参数!$C$58),0) -> 566.03774 | J18: =IF(J$4="运营",0_参数!$C$57/(1+0_参数!$C$58),0) -> 566.03774 | K18: =IF(K$4="运营",0_参数!$C$57/(1+0_参数!$C$58),0) -> 566.03774 | ... U18: =IF(U$4="运营",0_参数!$C$57/(1+0_参数!$C$58),0) -> 0 | V18: =IFERROR(SUMIF(D$4:U$4,"运营",D18:U18)/0_参数!$C$10,0) -> 566.03774
A19: 5 | B19: 硬件设备维保费 | C19: 万元 | D19: ='1-2_设备及软件'!$F$12/(1+0_参数!$C$58)*IF(D$5>0,INDEX(0_参数!$D$129:$R$129,D$5),0) -> 0 | E19: ='1-2_设备及软件'!$F$12/(1+0_参数!$C$58)*IF(E$5>0,INDEX(0_参数!$D$129:$R$129,E$5),0) -> 0 | F19: ='1-2_设备及软件'!$F$12/(1+0_参数!$C$58)*IF(F$5>0,INDEX(0_参数!$D$129:$R$129,F$5),0) -> 0 | G19: ='1-2_设备及软件'!$F$12/(1+0_参数!$C$58)*IF(G$5>0,INDEX(0_参数!$D$129:$R$129,G$5),0) -> 0 | H19: ='1-2_设备及软件'!$F$12/(1+0_参数!$C$58)*IF(H$5>0,INDEX(0_参数!$D$129:$R$129,H$5),0) -> 889.15094 | I19: ='1-2_设备及软件'!$F$12/(1+0_参数!$C$58)*IF(I$5>0,INDEX(0_参数!$D$129:$R$129,I$5),0) -> 889.15094 | J19: ='1-2_设备及软件'!$F$12/(1+0_参数!$C$58)*IF(J$5>0,INDEX(0_参数!$D$129:$R$129,J$5),0) -> 889.15094 | K19: ='1-2_设备及软件'!$F$12/(1+0_参数!$C$58)*IF(K$5>0,INDEX(0_参数!$D$129:$R$129,K$5),0) -> 1778.3019 | ... U19: ='1-2_设备及软件'!$F$12/(1+0_参数!$C$58)*IF(U$5>0,INDEX(0_参数!$D$129:$R$129,U$5),0) -> 0 | V19: =IFERROR(SUMIF(D$4:U$4,"运营",D19:U19)/0_参数!$C$10,0) -> 978.06604
A20: 6 | B20: 软件更新维护费 | C20: 万元 | D20: =IF(D$4="运营",'1-2_设备及软件'!$F$10/(1+0_参数!$C$58)*0_参数!$C$59,0) -> 0 | E20: =IF(E$4="运营",'1-2_设备及软件'!$F$10/(1+0_参数!$C$58)*0_参数!$C$59,0) -> 566.03774 | F20: =IF(F$4="运营",'1-2_设备及软件'!$F$10/(1+0_参数!$C$58)*0_参数!$C$59,0) -> 566.03774 | G20: =IF(G$4="运营",'1-2_设备及软件'!$F$10/(1+0_参数!$C$58)*0_参数!$C$59,0) -> 566.03774 | H20: =IF(H$4="运营",'1-2_设备及软件'!$F$10/(1+0_参数!$C$58)*0_参数!$C$59,0) -> 566.03774 | I20: =IF(I$4="运营",'1-2_设备及软件'!$F$10/(1+0_参数!$C$58)*0_参数!$C$59,0) -> 566.03774 | J20: =IF(J$4="运营",'1-2_设备及软件'!$F$10/(1+0_参数!$C$58)*0_参数!$C$59,0) -> 566.03774 | K20: =IF(K$4="运营",'1-2_设备及软件'!$F$10/(1+0_参数!$C$58)*0_参数!$C$59,0) -> 566.03774 | ... U20: =IF(U$4="运营",'1-2_设备及软件'!$F$10/(1+0_参数!$C$58)*0_参数!$C$59,0) -> 0 | V20: =IFERROR(SUMIF(D$4:U$4,"运营",D20:U20)/0_参数!$C$10,0) -> 566.03774
A21: 7 | B21: 机电设备维护费 | C21: 万元 | D21: =IF(D$4="运营",'1-2_设备及软件'!$F$22/(1+0_参数!$C$58)*0_参数!$C$60,0) -> 0 | E21: =IF(E$4="运营",'1-2_设备及软件'!$F$22/(1+0_参数!$C$58)*0_参数!$C$60,0) -> 126.43396 | F21: =IF(F$4="运营",'1-2_设备及软件'!$F$22/(1+0_参数!$C$58)*0_参数!$C$60,0) -> 126.43396 | G21: =IF(G$4="运营",'1-2_设备及软件'!$F$22/(1+0_参数!$C$58)*0_参数!$C$60,0) -> 126.43396 | H21: =IF(H$4="运营",'1-2_设备及软件'!$F$22/(1+0_参数!$C$58)*0_参数!$C$60,0) -> 126.43396 | I21: =IF(I$4="运营",'1-2_设备及软件'!$F$22/(1+0_参数!$C$58)*0_参数!$C$60,0) -> 126.43396 | J21: =IF(J$4="运营",'1-2_设备及软件'!$F$22/(1+0_参数!$C$58)*0_参数!$C$60,0) -> 126.43396 | K21: =IF(K$4="运营",'1-2_设备及软件'!$F$22/(1+0_参数!$C$58)*0_参数!$C$60,0) -> 126.43396 | ... U21: =IF(U$4="运营",'1-2_设备及软件'!$F$22/(1+0_参数!$C$58)*0_参数!$C$60,0) -> 0 | V21: =IFERROR(SUMIF(D$4:U$4,"运营",D21:U21)/0_参数!$C$10,0) -> 126.43396
A22: 8 | B22: 其他管理费用 | C22: 万元 | D22: =D17*0_参数!$C$69 -> 0 | E22: =E17*0_参数!$C$69 -> 102.2 | F22: =F17*0_参数!$C$69 -> 102.2 | G22: =G17*0_参数!$C$69 -> 102.2 | H22: =H17*0_参数!$C$69 -> 102.2 | I22: =I17*0_参数!$C$69 -> 102.2 | J22: =J17*0_参数!$C$69 -> 102.2 | K22: =K17*0_参数!$C$69 -> 102.2 | ... U22: =U17*0_参数!$C$69 -> 0 | V22: =IFERROR(SUMIF(D$4:U$4,"运营",D22:U22)/0_参数!$C$10,0) -> 102.2
A23: 9 | B23: 经营成本 = 1~8 | C23: 万元 | D23: =D13+D16+D17+D18+D19+D20+D21+D22 -> 0 | E23: =E13+E16+E17+E18+E19+E20+E21+E22 -> 3079.7316 | F23: =F13+F16+F17+F18+F19+F20+F21+F22 -> 3157.9766 | G23: =G13+G16+G17+G18+G19+G20+G21+G22 -> 3157.9766 | H23: =H13+H16+H17+H18+H19+H20+H21+H22 -> 4047.1276 | I23: =I13+I16+I17+I18+I19+I20+I21+I22 -> 4047.1276 | J23: =J13+J16+J17+J18+J19+J20+J21+J22 -> 4047.1276 | K23: =K13+K16+K17+K18+K19+K20+K21+K22 -> 4936.2785 | ... U23: =U13+U16+U17+U18+U19+U20+U21+U22 -> 0 | V23: =IFERROR(SUMIF(D$4:U$4,"运营",D23:U23)/0_参数!$C$10,0) -> 4128.2182
A24: 10 | B24: 折旧费 | C24: 万元 | D24: =5_折旧摊销!D$27 -> 0 | E24: =5_折旧摊销!E$27 -> 19019.003 | F24: =5_折旧摊销!F$27 -> 19019.003 | G24: =5_折旧摊销!G$27 -> 19019.003 | H24: =5_折旧摊销!H$27 -> 19019.003 | I24: =5_折旧摊销!I$27 -> 19019.003 | J24: =5_折旧摊销!J$27 -> 993.74712 | K24: =5_折旧摊销!K$27 -> 993.74712 | ... U24: =5_折旧摊销!U$27 -> 0 | V24: =IFERROR(SUMIF(D$4:U$4,"运营",D24:U24)/0_参数!$C$10,0) -> 10006.375
A25: 11 | B25: 摊销费 | C25: 万元 | D25: =5_折旧摊销!D$31 -> 0 | E25: =5_折旧摊销!E$31 -> 8.46 | F25: =5_折旧摊销!F$31 -> 8.46 | G25: =5_折旧摊销!G$31 -> 8.46 | H25: =5_折旧摊销!H$31 -> 8.46 | I25: =5_折旧摊销!I$31 -> 8.46 | J25: =5_折旧摊销!J$31 -> 0 | K25: =5_折旧摊销!K$31 -> 0 | ... U25: =5_折旧摊销!U$31 -> 0 | V25: =IFERROR(SUMIF(D$4:U$4,"运营",D25:U25)/0_参数!$C$10,0) -> 4.23
A26: 12 | B26: 利息支出（长期 + 流动资金借款） | C26: 万元 | D26: =IF(D$4="运营",11_还本付息!D$10+11_还本付息!D$19,0) -> 0 | E26: =IF(E$4="运营",11_还本付息!E$10+11_还本付息!E$19,0) -> 3139.8131 | F26: =IF(F$4="运营",11_还本付息!F$10+11_还本付息!F$19,0) -> 2851.8866 | G26: =IF(G$4="运营",11_还本付息!G$10+11_还本付息!G$19,0) -> 2542.7449 | H26: =IF(H$4="运营",11_还本付息!H$10+11_还本付息!H$19,0) -> 2230.8852 | I26: =IF(I$4="运营",11_还本付息!I$10+11_还本付息!I$19,0) -> 1919.0254 | J26: =IF(J$4="运营",11_还本付息!J$10+11_还本付息!J$19,0) -> 1607.1656 | K26: =IF(K$4="运营",11_还本付息!K$10+11_还本付息!K$19,0) -> 1295.3058 | ... U26: =IF(U$4="运营",11_还本付息!U$10+11_还本付息!U$19,0) -> 0 | V26: =IFERROR(SUMIF(D$4:U$4,"运营",D26:U26)/0_参数!$C$10,0) -> 1760.1585
A27: 13 | B27: 总成本费用 = 9 + 10 + 11 + 12 | C27: 万元 | D27: =D23+D24+D25+D26 -> 0 | E27: =E23+E24+E25+E26 -> 25247.008 | F27: =F23+F24+F25+F26 -> 25037.326 | G27: =G23+G24+G25+G26 -> 24728.185 | H27: =H23+H24+H25+H26 -> 25305.476 | I27: =I23+I24+I25+I26 -> 24993.616 | J27: =J23+J24+J25+J26 -> 6648.0403 | K27: =K23+K24+K25+K26 -> 7225.3314 | ... U27: =U23+U24+U25+U26 -> 0 | V27: =IFERROR(SUMIF(D$4:U$4,"运营",D27:U27)/0_参数!$C$10,0) -> 15898.982
B28: 其中：可变成本（燃料动力） | C28: 万元 | D28: =D16 -> 0 | E28: =E16 -> 641.98446 | F28: =F16 -> 720.22946 | G28: =G16 -> 720.22946 | H28: =H16 -> 720.22946 | I28: =I16 -> 720.22946 | J28: =J16 -> 720.22946 | K28: =K16 -> 720.22946 | ... U28: =U16 -> 0 | V28: =IFERROR(SUMIF(D$4:U$4,"运营",D28:U28)/0_参数!$C$10,0) -> 712.40496
B29: 其中：固定成本 | C29: 万元 | D29: =D27-D28 -> 0 | E29: =E27-E28 -> 24605.023 | F29: =F27-F28 -> 24317.097 | G29: =G27-G28 -> 24007.955 | H29: =H27-H28 -> 24585.246 | I29: =I27-I28 -> 24273.387 | J29: =J27-J28 -> 5927.8108 | K29: =K27-K28 -> 6505.102 | ... U29: =U27-U28 -> 0 | V29: =IFERROR(SUMIF(D$4:U$4,"运营",D29:U29)/0_参数!$C$10,0) -> 15186.577
B30: 经营进项税额（供附表 6） | C30: 万元 | D30: =D14*0_参数!$C$39+D15*0_参数!$C$41+D13*0_参数!$C$56+(D18+D19+D20+D21)*0_参数!$C$58 -> 0 | E30: =E14*0_参数!$C$39+E15*0_参数!$C$41+E13*0_参数!$C$56+(E18+E19+E20+E21)*0_参数!$C$58 -> 192.66659 | F30: =F14*0_参数!$C$39+F15*0_参数!$C$41+F13*0_参数!$C$56+(F18+F19+F20+F21)*0_参数!$C$58 -> 202.83844 | G30: =G14*0_参数!$C$39+G15*0_参数!$C$41+G13*0_参数!$C$56+(G18+G19+G20+G21)*0_参数!$C$58 -> 202.83844 | H30: =H14*0_参数!$C$39+H15*0_参数!$C$41+H13*0_参数!$C$56+(H18+H19+H20+H21)*0_参数!$C$58 -> 256.1875 | I30: =I14*0_参数!$C$39+I15*0_参数!$C$41+I13*0_参数!$C$56+(I18+I19+I20+I21)*0_参数!$C$58 -> 256.1875 | J30: =J14*0_参数!$C$39+J15*0_参数!$C$41+J13*0_参数!$C$56+(J18+J19+J20+J21)*0_参数!$C$58 -> 256.1875 | K30: =K14*0_参数!$C$39+K15*0_参数!$C$41+K13*0_参数!$C$56+(K18+K19+K20+K21)*0_参数!$C$58 -> 309.53655 | ... U30: =U14*0_参数!$C$39+U15*0_参数!$C$41+U13*0_参数!$C$56+(U18+U19+U20+U21)*0_参数!$C$58 -> 0 | V30: =IFERROR(SUMIF(D$4:U$4,"运营",D30:U30)/0_参数!$C$10,0) -> 260.50522

Sheet 5_折旧摊销
A1: 附表 5 固定资产折旧与无形及递延资产摊销估算表
A2: 单位：万元。原值 = 直接费（按参数 F6 决定是否扣减进项税）+ 分摊的其他费用 / 预备费 / 建设期利息（按直接费占比分摊）；分三类折旧年限
A3: 序号 | B3: 项目 \ 年份 | C3: 单位/说明 | D3: 1 | E3: =D3+1 -> 2 | F3: =E3+1 -> 3 | G3: =F3+1 -> 4 | H3: =G3+1 -> 5 | I3: =H3+1 -> 6 | J3: =I3+1 -> 7 | K3: =J3+1 -> 8 | L3: =K3+1 -> 9 | ... U3: =T3+1 -> 18 | V3: 合计/平均
B4: 阶段 | D4: =IF(D$3<=0_参数!$C$9,"建设",IF(D$3<=0_参数!$C$9+0_参数!$C$10,"运营","")) -> 建设 | E4: =IF(E$3<=0_参数!$C$9,"建设",IF(E$3<=0_参数!$C$9+0_参数!$C$10,"运营","")) -> 运营 | F4: =IF(F$3<=0_参数!$C$9,"建设",IF(F$3<=0_参数!$C$9+0_参数!$C$10,"运营","")) -> 运营 | G4: =IF(G$3<=0_参数!$C$9,"建设",IF(G$3<=0_参数!$C$9+0_参数!$C$10,"运营","")) -> 运营 | H4: =IF(H$3<=0_参数!$C$9,"建设",IF(H$3<=0_参数!$C$9+0_参数!$C$10,"运营","")) -> 运营 | I4: =IF(I$3<=0_参数!$C$9,"建设",IF(I$3<=0_参数!$C$9+0_参数!$C$10,"运营","")) -> 运营 | J4: =IF(J$3<=0_参数!$C$9,"建设",IF(J$3<=0_参数!$C$9+0_参数!$C$10,"运营","")) -> 运营 | K4: =IF(K$3<=0_参数!$C$9,"建设",IF(K$3<=0_参数!$C$9+0_参数!$C$10,"运营","")) -> 运营 | ... U4: =IF(U$3<=0_参数!$C$9,"建设",IF(U$3<=0_参数!$C$9+0_参数!$C$10,"运营",""))
B5: 运营年序号 | D5: =IF(D$4="运营",D$3-0_参数!$C$9,0) -> 0 | E5: =IF(E$4="运营",E$3-0_参数!$C$9,0) -> 1 | F5: =IF(F$4="运营",F$3-0_参数!$C$9,0) -> 2 | G5: =IF(G$4="运营",G$3-0_参数!$C$9,0) -> 3 | H5: =IF(H$4="运营",H$3-0_参数!$C$9,0) -> 4 | I5: =IF(I$4="运营",I$3-0_参数!$C$9,0) -> 5 | J5: =IF(J$4="运营",J$3-0_参数!$C$9,0) -> 6 | K5: =IF(K$4="运营",K$3-0_参数!$C$9,0) -> 7 | ... U5: =IF(U$4="运营",U$3-0_参数!$C$9,0) -> 0
B6: 建设年序号 | D6: =IF(D$4="建设",D$3,0) -> 1 | E6: =IF(E$4="建设",E$3,0) -> 0 | F6: =IF(F$4="建设",F$3,0) -> 0 | G6: =IF(G$4="建设",G$3,0) -> 0 | H6: =IF(H$4="建设",H$3,0) -> 0 | I6: =IF(I$4="建设",I$3,0) -> 0 | J6: =IF(J$4="建设",J$3,0) -> 0 | K6: =IF(K$4="建设",K$3,0) -> 0 | ... U6: =IF(U$4="建设",U$3,0) -> 0
B7: 原值计算
B8: 建筑类直接费（净税） | C8: =1_总投资估算!$F$44-1_总投资估算!$F$38 -> 2579.633
B9: 基础设施设备直接费（净税） | C9: =1_总投资估算!$F$43-IF(0_参数!$C$77=1,1_总投资估算!$F$43/(1+0_参数!$C$81)*0_参数!$C$81,0) -> 11860.177
B10: 算力设备直接费（净税） | C10: =1_总投资估算!$F$42-IF(0_参数!$C$77=1,1_总投资估算!$F$42/(1+0_参数!$C$81)*0_参数!$C$81,0) -> 83407.08
B11: 待分摊费用 = 其他费用(固定资产) + 预备费 + 建设期利息 | C11: =1_总投资估算!$F$40+1_总投资估算!$G$26+1_总投资估算!$G$30 -> 13447.161
B12: 建筑类原值 | C12: =C8+C11*C8/(C8+C9+C10) -> 2934.1537
B13: 基础设施设备原值 | C13: =C9+C11*C9/(C8+C9+C10) -> 13490.129
B14: 算力设备原值 | C14: =C10+C11*C10/(C8+C9+C10) -> 94869.768
B15: 固定资产原值合计 | C15: =C12+C13+C14 -> 111294.05
B16: 递延资产原值 | C16: =1_总投资估算!$F$41 -> 42.3
A18: 1 | B18: 建筑类 折旧费 | C18: 万元 | D18: =IF(AND(D$4="运营",D$5<=0_参数!$C$72),5_折旧摊销!$C$12*(1-0_参数!$C$75)/0_参数!$C$72,0) -> 0 | E18: =IF(AND(E$4="运营",E$5<=0_参数!$C$72),5_折旧摊销!$C$12*(1-0_参数!$C$75)/0_参数!$C$72,0) -> 139.3723 | F18: =IF(AND(F$4="运营",F$5<=0_参数!$C$72),5_折旧摊销!$C$12*(1-0_参数!$C$75)/0_参数!$C$72,0) -> 139.3723 | G18: =IF(AND(G$4="运营",G$5<=0_参数!$C$72),5_折旧摊销!$C$12*(1-0_参数!$C$75)/0_参数!$C$72,0) -> 139.3723 | H18: =IF(AND(H$4="运营",H$5<=0_参数!$C$72),5_折旧摊销!$C$12*(1-0_参数!$C$75)/0_参数!$C$72,0) -> 139.3723 | I18: =IF(AND(I$4="运营",I$5<=0_参数!$C$72),5_折旧摊销!$C$12*(1-0_参数!$C$75)/0_参数!$C$72,0) -> 139.3723 | J18: =IF(AND(J$4="运营",J$5<=0_参数!$C$72),5_折旧摊销!$C$12*(1-0_参数!$C$75)/0_参数!$C$72,0) -> 139.3723 | K18: =IF(AND(K$4="运营",K$5<=0_参数!$C$72),5_折旧摊销!$C$12*(1-0_参数!$C$75)/0_参数!$C$72,0) -> 139.3723 | ... U18: =IF(AND(U$4="运营",U$5<=0_参数!$C$72),5_折旧摊销!$C$12*(1-0_参数!$C$75)/0_参数!$C$72,0) -> 0 | V18: =SUM(D18:U18) -> 1393.723
B19: 建筑类 期末净值 | C19: 万元 | D19: =IF(D$4="",0,5_折旧摊销!$C$12-SUM($D18:D18)) -> 2934.1537 | E19: =IF(E$4="",0,5_折旧摊销!$C$12-SUM($D18:E18)) -> 2794.7814 | F19: =IF(F$4="",0,5_折旧摊销!$C$12-SUM($D18:F18)) -> 2655.4091 | G19: =IF(G$4="",0,5_折旧摊销!$C$12-SUM($D18:G18)) -> 2516.0368 | H19: =IF(H$4="",0,5_折旧摊销!$C$12-SUM($D18:H18)) -> 2376.6645 | I19: =IF(I$4="",0,5_折旧摊销!$C$12-SUM($D18:I18)) -> 2237.2922 | J19: =IF(J$4="",0,5_折旧摊销!$C$12-SUM($D18:J18)) -> 2097.9199 | K19: =IF(K$4="",0,5_折旧摊销!$C$12-SUM($D18:K18)) -> 1958.5476 | ... U19: =IF(U$4="",0,5_折旧摊销!$C$12-SUM($D18:U18)) -> 0 | V19: =INDEX(D19:U19,0_参数!$C$9+0_参数!$C$10) -> 1540.4307
A20: 2 | B20: 基础设施设备 折旧费 | C20: 万元 | D20: =IF(AND(D$4="运营",D$5<=0_参数!$C$73),5_折旧摊销!$C$13*(1-0_参数!$C$75)/0_参数!$C$73,0) -> 0 | E20: =IF(AND(E$4="运营",E$5<=0_参数!$C$73),5_折旧摊销!$C$13*(1-0_参数!$C$75)/0_参数!$C$73,0) -> 854.37482 | F20: =IF(AND(F$4="运营",F$5<=0_参数!$C$73),5_折旧摊销!$C$13*(1-0_参数!$C$75)/0_参数!$C$73,0) -> 854.37482 | G20: =IF(AND(G$4="运营",G$5<=0_参数!$C$73),5_折旧摊销!$C$13*(1-0_参数!$C$75)/0_参数!$C$73,0) -> 854.37482 | H20: =IF(AND(H$4="运营",H$5<=0_参数!$C$73),5_折旧摊销!$C$13*(1-0_参数!$C$75)/0_参数!$C$73,0) -> 854.37482 | I20: =IF(AND(I$4="运营",I$5<=0_参数!$C$73),5_折旧摊销!$C$13*(1-0_参数!$C$75)/0_参数!$C$73,0) -> 854.37482 | J20: =IF(AND(J$4="运营",J$5<=0_参数!$C$73),5_折旧摊销!$C$13*(1-0_参数!$C$75)/0_参数!$C$73,0) -> 854.37482 | K20: =IF(AND(K$4="运营",K$5<=0_参数!$C$73),5_折旧摊销!$C$13*(1-0_参数!$C$75)/0_参数!$C$73,0) -> 854.37482 | ... U20: =IF(AND(U$4="运营",U$5<=0_参数!$C$73),5_折旧摊销!$C$13*(1-0_参数!$C$75)/0_参数!$C$73,0) -> 0 | V20: =SUM(D20:U20) -> 8543.7482
B21: 基础设施设备 期末净值 | C21: 万元 | D21: =IF(D$4="",0,5_折旧摊销!$C$13-SUM($D20:D20)) -> 13490.129 | E21: =IF(E$4="",0,5_折旧摊销!$C$13-SUM($D20:E20)) -> 12635.754 | F21: =IF(F$4="",0,5_折旧摊销!$C$13-SUM($D20:F20)) -> 11781.379 | G21: =IF(G$4="",0,5_折旧摊销!$C$13-SUM($D20:G20)) -> 10927.004 | H21: =IF(H$4="",0,5_折旧摊销!$C$13-SUM($D20:H20)) -> 10072.629 | I21: =IF(I$4="",0,5_折旧摊销!$C$13-SUM($D20:I20)) -> 9218.2547 | J21: =IF(J$4="",0,5_折旧摊销!$C$13-SUM($D20:J20)) -> 8363.8798 | K21: =IF(K$4="",0,5_折旧摊销!$C$13-SUM($D20:K20)) -> 7509.505 | ... U21: =IF(U$4="",0,5_折旧摊销!$C$13-SUM($D20:U20)) -> 0 | V21: =INDEX(D21:U21,0_参数!$C$9+0_参数!$C$10) -> 4946.3805
A22: 3 | B22: 算力设备 折旧费 | C22: 万元 | D22: =IF(AND(D$4="运营",D$5<=0_参数!$C$74),5_折旧摊销!$C$14*(1-0_参数!$C$75)/0_参数!$C$74,0) -> 0 | E22: =IF(AND(E$4="运营",E$5<=0_参数!$C$74),5_折旧摊销!$C$14*(1-0_参数!$C$75)/0_参数!$C$74,0) -> 18025.256 | F22: =IF(AND(F$4="运营",F$5<=0_参数!$C$74),5_折旧摊销!$C$14*(1-0_参数!$C$75)/0_参数!$C$74,0) -> 18025.256 | G22: =IF(AND(G$4="运营",G$5<=0_参数!$C$74),5_折旧摊销!$C$14*(1-0_参数!$C$75)/0_参数!$C$74,0) -> 18025.256 | H22: =IF(AND(H$4="运营",H$5<=0_参数!$C$74),5_折旧摊销!$C$14*(1-0_参数!$C$75)/0_参数!$C$74,0) -> 18025.256 | I22: =IF(AND(I$4="运营",I$5<=0_参数!$C$74),5_折旧摊销!$C$14*(1-0_参数!$C$75)/0_参数!$C$74,0) -> 18025.256 | J22: =IF(AND(J$4="运营",J$5<=0_参数!$C$74),5_折旧摊销!$C$14*(1-0_参数!$C$75)/0_参数!$C$74,0) -> 0 | K22: =IF(AND(K$4="运营",K$5<=0_参数!$C$74),5_折旧摊销!$C$14*(1-0_参数!$C$75)/0_参数!$C$74,0) -> 0 | ... U22: =IF(AND(U$4="运营",U$5<=0_参数!$C$74),5_折旧摊销!$C$14*(1-0_参数!$C$75)/0_参数!$C$74,0) -> 0 | V22: =SUM(D22:U22) -> 90126.28
B23: 算力设备 期末净值 | C23: 万元 | D23: =IF(D$4="",0,5_折旧摊销!$C$14-SUM($D22:D22)) -> 94869.768 | E23: =IF(E$4="",0,5_折旧摊销!$C$14-SUM($D22:E22)) -> 76844.512 | F23: =IF(F$4="",0,5_折旧摊销!$C$14-SUM($D22:F22)) -> 58819.256 | G23: =IF(G$4="",0,5_折旧摊销!$C$14-SUM($D22:G22)) -> 40794 | H23: =IF(H$4="",0,5_折旧摊销!$C$14-SUM($D22:H22)) -> 22768.744 | I23: =IF(I$4="",0,5_折旧摊销!$C$14-SUM($D22:I22)) -> 4743.4884 | J23: =IF(J$4="",0,5_折旧摊销!$C$14-SUM($D22:J22)) -> 4743.4884 | K23: =IF(K$4="",0,5_折旧摊销!$C$14-SUM($D22:K22)) -> 4743.4884 | ... U23: =IF(U$4="",0,5_折旧摊销!$C$14-SUM($D22:U22)) -> 0 | V23: =INDEX(D23:U23,0_参数!$C$9+0_参数!$C$10) -> 4743.4884
B24: （预留）
B25: （预留）
B26: （预留）
A27: 4 | B27: 固定资产折旧费合计 | C27: 万元 | D27: =D18+D20+D22 -> 0 | E27: =E18+E20+E22 -> 19019.003 | F27: =F18+F20+F22 -> 19019.003 | G27: =G18+G20+G22 -> 19019.003 | H27: =H18+H20+H22 -> 19019.003 | I27: =I18+I20+I22 -> 19019.003 | J27: =J18+J20+J22 -> 993.74712 | K27: =K18+K20+K22 -> 993.74712 | ... U27: =U18+U20+U22 -> 0 | V27: =SUM(D27:U27) -> 100063.75
B28: 固定资产期末净值合计 | C28: 万元 | D28: =D19+D21+D23 -> 111294.05 | E28: =E19+E21+E23 -> 92275.048 | F28: =F19+F21+F23 -> 73256.045 | G28: =G19+G21+G23 -> 54237.041 | H28: =H19+H21+H23 -> 35218.038 | I28: =I19+I21+I23 -> 16199.035 | J28: =J19+J21+J23 -> 15205.288 | K28: =K19+K21+K23 -> 14211.541 | ... U28: =U19+U21+U23 -> 0 | V28: =INDEX(D28:U28,0_参数!$C$9+0_参数!$C$10) -> 11230.3
B29: 计算期末固定资产余值（供附表 8 回收） | C29: 万元 | D29: =IF(D$3=0_参数!$C$9+0_参数!$C$10,D28,0) -> 0 | E29: =IF(E$3=0_参数!$C$9+0_参数!$C$10,E28,0) -> 0 | F29: =IF(F$3=0_参数!$C$9+0_参数!$C$10,F28,0) -> 0 | G29: =IF(G$3=0_参数!$C$9+0_参数!$C$10,G28,0) -> 0 | H29: =IF(H$3=0_参数!$C$9+0_参数!$C$10,H28,0) -> 0 | I29: =IF(I$3=0_参数!$C$9+0_参数!$C$10,I28,0) -> 0 | J29: =IF(J$3=0_参数!$C$9+0_参数!$C$10,J28,0) -> 0 | K29: =IF(K$3=0_参数!$C$9+0_参数!$C$10,K28,0) -> 0 | ... U29: =IF(U$3=0_参数!$C$9+0_参数!$C$10,U28,0) -> 0 | V29: =SUM(D29:U29) -> 11230.3
B30: （预留）
A31: 5 | B31: 递延资产摊销费 | C31: 万元 | D31: =IF(AND(D$4="运营",D$5<=0_参数!$C$76),5_折旧摊销!$C$16/0_参数!$C$76,0) -> 0 | E31: =IF(AND(E$4="运营",E$5<=0_参数!$C$76),5_折旧摊销!$C$16/0_参数!$C$76,0) -> 8.46 | F31: =IF(AND(F$4="运营",F$5<=0_参数!$C$76),5_折旧摊销!$C$16/0_参数!$C$76,0) -> 8.46 | G31: =IF(AND(G$4="运营",G$5<=0_参数!$C$76),5_折旧摊销!$C$16/0_参数!$C$76,0) -> 8.46 | H31: =IF(AND(H$4="运营",H$5<=0_参数!$C$76),5_折旧摊销!$C$16/0_参数!$C$76,0) -> 8.46 | I31: =IF(AND(I$4="运营",I$5<=0_参数!$C$76),5_折旧摊销!$C$16/0_参数!$C$76,0) -> 8.46 | J31: =IF(AND(J$4="运营",J$5<=0_参数!$C$76),5_折旧摊销!$C$16/0_参数!$C$76,0) -> 0 | K31: =IF(AND(K$4="运营",K$5<=0_参数!$C$76),5_折旧摊销!$C$16/0_参数!$C$76,0) -> 0 | ... U31: =IF(AND(U$4="运营",U$5<=0_参数!$C$76),5_折旧摊销!$C$16/0_参数!$C$76,0) -> 0 | V31: =SUM(D31:U31) -> 42.3
B32: 递延资产期末净值 | C32: 万元 | D32: =IF(D$4="",0,5_折旧摊销!$C$16-SUM($D31:D31)) -> 42.3 | E32: =IF(E$4="",0,5_折旧摊销!$C$16-SUM($D31:E31)) -> 33.84 | F32: =IF(F$4="",0,5_折旧摊销!$C$16-SUM($D31:F31)) -> 25.38 | G32: =IF(G$4="",0,5_折旧摊销!$C$16-SUM($D31:G31)) -> 16.92 | H32: =IF(H$4="",0,5_折旧摊销!$C$16-SUM($D31:H31)) -> 8.46 | I32: =IF(I$4="",0,5_折旧摊销!$C$16-SUM($D31:I31)) -> 0 | J32: =IF(J$4="",0,5_折旧摊销!$C$16-SUM($D31:J31)) -> 0 | K32: =IF(K$4="",0,5_折旧摊销!$C$16-SUM($D31:K31)) -> 0 | ... U32: =IF(U$4="",0,5_折旧摊销!$C$16-SUM($D31:U31)) -> 0 | V32: =INDEX(D32:U32,0_参数!$C$9+0_参数!$C$10) -> 0

Sheet 6_收入税金
A1: 附表 6 营业收入、增值税及税金附加估算表
A2: 单位：万元。收入 = 可售单元 × 投产比例 × 售卖比例 × 单价 × 12；含税→不含税按参数 D4 还原；增值税按销项 − 进项 − 期初留抵计算
A3: 序号 | B3: 项目 \ 年份 | C3: 单位/说明 | D3: 1 | E3: =D3+1 -> 2 | F3: =E3+1 -> 3 | G3: =F3+1 -> 4 | H3: =G3+1 -> 5 | I3: =H3+1 -> 6 | J3: =I3+1 -> 7 | K3: =J3+1 -> 8 | L3: =K3+1 -> 9 | ... U3: =T3+1 -> 18 | V3: 合计/平均
B4: 阶段 | D4: =IF(D$3<=0_参数!$C$9,"建设",IF(D$3<=0_参数!$C$9+0_参数!$C$10,"运营","")) -> 建设 | E4: =IF(E$3<=0_参数!$C$9,"建设",IF(E$3<=0_参数!$C$9+0_参数!$C$10,"运营","")) -> 运营 | F4: =IF(F$3<=0_参数!$C$9,"建设",IF(F$3<=0_参数!$C$9+0_参数!$C$10,"运营","")) -> 运营 | G4: =IF(G$3<=0_参数!$C$9,"建设",IF(G$3<=0_参数!$C$9+0_参数!$C$10,"运营","")) -> 运营 | H4: =IF(H$3<=0_参数!$C$9,"建设",IF(H$3<=0_参数!$C$9+0_参数!$C$10,"运营","")) -> 运营 | I4: =IF(I$3<=0_参数!$C$9,"建设",IF(I$3<=0_参数!$C$9+0_参数!$C$10,"运营","")) -> 运营 | J4: =IF(J$3<=0_参数!$C$9,"建设",IF(J$3<=0_参数!$C$9+0_参数!$C$10,"运营","")) -> 运营 | K4: =IF(K$3<=0_参数!$C$9,"建设",IF(K$3<=0_参数!$C$9+0_参数!$C$10,"运营","")) -> 运营 | ... U4: =IF(U$3<=0_参数!$C$9,"建设",IF(U$3<=0_参数!$C$9+0_参数!$C$10,"运营",""))
B5: 运营年序号 | D5: =IF(D$4="运营",D$3-0_参数!$C$9,0) -> 0 | E5: =IF(E$4="运营",E$3-0_参数!$C$9,0) -> 1 | F5: =IF(F$4="运营",F$3-0_参数!$C$9,0) -> 2 | G5: =IF(G$4="运营",G$3-0_参数!$C$9,0) -> 3 | H5: =IF(H$4="运营",H$3-0_参数!$C$9,0) -> 4 | I5: =IF(I$4="运营",I$3-0_参数!$C$9,0) -> 5 | J5: =IF(J$4="运营",J$3-0_参数!$C$9,0) -> 6 | K5: =IF(K$4="运营",K$3-0_参数!$C$9,0) -> 7 | ... U5: =IF(U$4="运营",U$3-0_参数!$C$9,0) -> 0
B6: 建设年序号 | D6: =IF(D$4="建设",D$3,0) -> 1 | E6: =IF(E$4="建设",E$3,0) -> 0 | F6: =IF(F$4="建设",F$3,0) -> 0 | G6: =IF(G$4="建设",G$3,0) -> 0 | H6: =IF(H$4="建设",H$3,0) -> 0 | I6: =IF(I$4="建设",I$3,0) -> 0 | J6: =IF(J$4="建设",J$3,0) -> 0 | K6: =IF(K$4="建设",K$3,0) -> 0 | ... U6: =IF(U$4="建设",U$3,0) -> 0
A7: 1 | B7: 可售计价单元（投运） | C7: 台 | D7: =IF(D$4="运营",0_参数!$C$26*4_总成本费用!D$7,0) -> 0 | E7: =IF(E$4="运营",0_参数!$C$26*4_总成本费用!E$7,0) -> 168 | F7: =IF(F$4="运营",0_参数!$C$26*4_总成本费用!F$7,0) -> 168 | G7: =IF(G$4="运营",0_参数!$C$26*4_总成本费用!G$7,0) -> 168 | H7: =IF(H$4="运营",0_参数!$C$26*4_总成本费用!H$7,0) -> 168 | I7: =IF(I$4="运营",0_参数!$C$26*4_总成本费用!I$7,0) -> 168 | J7: =IF(J$4="运营",0_参数!$C$26*4_总成本费用!J$7,0) -> 168 | K7: =IF(K$4="运营",0_参数!$C$26*4_总成本费用!K$7,0) -> 168 | ... U7: =IF(U$4="运营",0_参数!$C$26*4_总成本费用!U$7,0) -> 0
A8: 2 | B8: 售卖比例 | D8: =4_总成本费用!D$8 -> 0 | E8: =4_总成本费用!E$8 -> 0.8 | F8: =4_总成本费用!F$8 -> 0.9 | G8: =4_总成本费用!G$8 -> 0.9 | H8: =4_总成本费用!H$8 -> 0.9 | I8: =4_总成本费用!I$8 -> 0.9 | J8: =4_总成本费用!J$8 -> 0.9 | K8: =4_总成本费用!K$8 -> 0.9 | ... U8: =4_总成本费用!U$8 -> 0
A9: 3 | B9: 算力单价（含税） | C9: 万元/台/月 | D9: =IF(D$4="运营",0_参数!$C$46,0) -> 0 | E9: =IF(E$4="运营",0_参数!$C$46,0) -> 14 | F9: =IF(F$4="运营",0_参数!$C$46,0) -> 14 | G9: =IF(G$4="运营",0_参数!$C$46,0) -> 14 | H9: =IF(H$4="运营",0_参数!$C$46,0) -> 14 | I9: =IF(I$4="运营",0_参数!$C$46,0) -> 14 | J9: =IF(J$4="运营",0_参数!$C$46,0) -> 14 | K9: =IF(K$4="运营",0_参数!$C$46,0) -> 14 | ... U9: =IF(U$4="运营",0_参数!$C$46,0) -> 0
A10: 4 | B10: 营业收入（含税） | C10: 万元 | D10: =D7*D8*D9*12 -> 0 | E10: =E7*E8*E9*12 -> 22579.2 | F10: =F7*F8*F9*12 -> 25401.6 | G10: =G7*G8*G9*12 -> 25401.6 | H10: =H7*H8*H9*12 -> 25401.6 | I10: =I7*I8*I9*12 -> 25401.6 | J10: =J7*J8*J9*12 -> 25401.6 | K10: =K7*K8*K9*12 -> 25401.6 | ... U10: =U7*U8*U9*12 -> 0 | V10: =IFERROR(SUMIF(D$4:U$4,"运营",D10:U10)/0_参数!$C$10,0) -> 25119.36
A11: 5 | B11: 营业收入（不含税） | C11: 万元 | D11: =D10/(1+0_参数!$C$47) -> 0 | E11: =E10/(1+0_参数!$C$47) -> 21301.132 | F11: =F10/(1+0_参数!$C$47) -> 23963.774 | G11: =G10/(1+0_参数!$C$47) -> 23963.774 | H11: =H10/(1+0_参数!$C$47) -> 23963.774 | I11: =I10/(1+0_参数!$C$47) -> 23963.774 | J11: =J10/(1+0_参数!$C$47) -> 23963.774 | K11: =K10/(1+0_参数!$C$47) -> 23963.774 | ... U11: =U10/(1+0_参数!$C$47) -> 0 | V11: =IFERROR(SUMIF(D$4:U$4,"运营",D11:U11)/0_参数!$C$10,0) -> 23697.509
